Workbook
Name \0: #REF!
Name \0: #REF!
Name \A: #REF!
Name \A: #REF!
Name \B: #REF!
Name \B: #REF!
Name \P: #REF!
Name \P: #REF!
Name \Q: #REF!
Name \Q: #REF!
Name \S: #REF!
Name \S: #REF!
Name \W: #REF!
Name \W: #REF!
Name Client: #REF!
Name Client: #REF!
Name CurrencyConversion: #REF!
Name CurrencyConversion: #REF!
Name DollarGaugeBase: #REF!
Name DollarGaugeBase: #REF!
Name ee: #REF!
Name ee: #REF!
Name eu: #REF!
Name eu: #REF!
Name LocalGauge: #REF!
Name LocalGauge: #REF!
Name LocalGaugeBase: #REF!
Name LocalGaugeBase: #REF!
Name ma: #REF!
Name ma: #REF!
Name mary: #REF!
Name mary: #REF!
Name mbgs: #REF!
Name mbgs: #REF!
Name me: #REF!
Name me: #REF!
Name mi: #REF!
Name mi: #REF!
Name mo: #REF!
Name mo: #REF!
Name my: #REF!
Name my: #REF!
Name TAnterior: #REF!
Name TAnterior: #REF!
Name tel: #REF!
Name tel: #REF!
Name TotalAssets: #REF!
Name TotalAssets: #REF!
Name TotalRevenue: #REF!
Name TotalRevenue: #REF!

Sheet Resumo Conceitual
B8: NBC TA 320 (R1) [DOU 05/09/16] - Materialidade no Planejamento e na Execução da Auditoria - [ISA 320]
B9: 9. Para fins das normas de auditoria, materialidade para execução da auditoria significa o valor ou valores fixados pelo auditor, inferiores ao considerado relevante para as demonstrações contábeis como um todo, para adequadamente reduzir a um nível baixo a probabilidade de que as distorções não corrigidas e não detectadas em conjunto, excedam a materialidade para as demonstrações contábeis como um todo. Se aplicável, materialidade para execução da auditoria refere-se, também, ao valor ou valores fixados pelo auditor inferiores ao nível ou níveis de materialidade para classes específicas de transações, saldos contábeis e divulgações.
B11: Determinação da materialidade Na definição da estratégia global de auditoria, que deve determinar a materialidade de acordo com as NBC TA 320 (R1) [DOU 05/09/16] - Materialidade no Planejamento e na Execução da Auditoria - [ISA 320]. [Fonte: ISA 320.10] Materialidade para as demonstrações contábeis como um todo é determinado com base em nosso entendimento das necessidades e expectativas dos usuários. Expectativas dos usuários podem variar em função do grau de incerteza inerente associada à medição de itens específicos nas demonstrações financeiras, entre outras considerações. Por exemplo, o fato de que as demonstrações financeiras incluem grandes disposições com um alto grau de incerteza das estimativas (por exemplo, provisões para créditos de seguros, no caso de uma companhia de seguros, custos de desmantelamento de plataformas de petróleo no caso de uma empresa de petróleo, ou, de modo mais geral, ações judiciais contra a entidade) podem influenciar a avaliação do usuário de materialidade.
B13: Benchmark A determinação do valor de referência adequado inclui a consideração de ganhos e outros fatores relevantes da entidade. Fatores que podem afetar a identificação de uma referência adequada incluem: [Fonte: ISA 320.A3] Fator - Os elementos das demonstrações financeiras [Fonte: ISA 320.A3] Exemplos - ativos, passivos, patrimônio líquido, receita e despesas. [Fonte: ISA 320.A3] Fator - Se há itens em que a atenção dos usuários das demonstrações contábeis da entidade particular, tende a ser focado [Fonte: ISA 320.A3] Exemplos - Para efeitos de avaliação de desempenho financeiro usuários tendem a se concentrar sobre o lucro, a receita ou ativos líquidos. [Fonte: ISA 320.A3]
B15: Fatores que podem afetar a identificação de uma referência adequada incluem: [Fonte: ISA 320.A3] Fator - A natureza da entidade, em que a entidade está em seu ciclo de vida e da indústria e ambiente econômico em que a entidade opera [Fonte: ISA 320.A3] Exemplos - · Para entidades com fins lucrativos, o lucro ou prejuízo antes de impostos das operações continuadas é muitas vezes usado como referência [Fonte: ISA 320.A4] · Para entidades sem fins lucrativos, uma referência adequada pode ser ativos totais ou despesas totais · Para entidades de baixa rentabilidade e entidades que tenham atingido os seus pontos de equilíbrio, uma referência adequada pode ser o total das receitas ou total dos ativos.
B17: Determinar a adequação do percentual do valor de referência escolhido envolve o exercício de julgamento profissional. [Fonte: ISA 320.A7] As faixas percentuais em (abaixo) são destinados a fornecer uma orientação ao exercer nosso julgamento. Nosso julgamento sobre se o percentual é adequado em relação ao conjunto relevante de porcentagens (normalmente cai entre 3-10% (inclusive) para um ponto de referência líquida ou cai entre 0,5-3% (inclusive) para um ponto de referência bruto) pode ser influenciado por fatores relacionados na nossa metodologia, bem como os seguintes fatores: * A concentração da propriedade e / ou gestão * a renegociação das dívidas * Ambiente de negócios * Outras sensibilidades
B19: Materialidade Desempenho (PM) Vamos determinar a materialidade de desempenho para fins de avaliação dos riscos de distorção relevante e determinar a natureza, época e extensão dos procedimentos adicionais de auditoria. [ISA 320,11] Materialidade Desempenho (PM) (que, como definido, é um ou mais valores) é menor que a Materialidade(M) para as demonstrações contábeis como um todo e reduz a um nível apropriadamente baixo a probabilidade de que o agregado de distorções não corrigidas e não detectadas nas demonstrações financeiras ultrapasse a materialidade para as demonstrações financeiras como um todo. Esta probabilidade é referido como "o risco de agregação". [Fonte: ISA 320,9 Fonte: ISA 320.A12]
B21: Risco Agregação é a probabilidade de que o agregado de distorções não corrigidas e não detectadas nas demonstrações financeiras (e, se aplicável, as contas significativas ou divulgações) ultrapassa a materialidade para as demonstrações contábeis como um todo (e, se for o caso, conta significativo inferior / divulgação materialidade). Como o risco de agregação aumenta, a materialidade desempenho(PM) diminui. [Fonte: ISA 320,9 Fonte: ISA 320.A12] A presença de um ou mais dos seguintes factores podem indicar um maior risco de agregação e, portanto, uma PM inferior pode ser apropriado: · Ambiente de controle deficiente · Um histórico de deficiências significativas e / ou um número elevado de deficiências no controle interno · Alta rotatividade de quadros superiores ou pessoal-chave de relato financeiro · Aumento do número de questões contábeis que requerem julgamento significativo e / ou mais estimativas com alta incerteza de estimativa, e · Uma entidade que atua em uma série de locais.
B23: Distorção Auditoria após limiar ("AMPT") Vamos designar uma quantidade abaixo do qual as distorções identificadas durante a auditoria seria claramente trivial. Este montante é referido como Audit Misstatement Posting Threshold ("AMPT"). [Fonte: ISA 450,5 Fonte: ISA 450,15 (a)] "Claramente trivial" não é outra expressão para "não materiais". Assuntos que são claramente triviais serão de uma (menor) ordem completamente diferente de magnitude do que a materialidade, e serão assuntos que são claramente irrelevantes, se tomados individualmente ou em conjunto, e se julgado por qualquer critério de dimensão, natureza ou circunstâncias. [Fonte: ISA 450.A2] A AMPT cai normalmente entre 3 e 5 por cento de materialidade para as demonstrações contábeis como um todo.

Sheet Materialidade
B2: S3 Saude
B3: Cálculo de Materialidade
B4: Data base: 31/12/2023
B5: Valores expressos em R$ c/ centavos omitidos
B7: Objetivo:
B8: =CONCATENATE("Calcular a materiality (M), performance materiality (PM) e AMPT para os trabalhos de auditoria da"&" "&B2&", considerando os critérios elencados na NBC TA 320 (R1) [DOU 05/09/16] - Materialidade no Planejamento e na Execução da Auditoria - [ISA 320] para escolha do melhor benchmark.") -> Calcular a materiality (M), performance materiality (PM) e AMPT para os trabalhos de auditoria da S3 Saude, considerando os critérios elencados na NBC TA 320 (R1) [DOU 05/09/16] - Materialidade no Planejamento e na Execução da Auditoria - [ISA 320] para escolha do melhor benchmark.
B9: http://www1.cfc.org.br/sisweb/sre/detalhes_sre.aspx?codigo=2016/NBCTA320(R1) / | F9: NBC TA 320
B10: https://www.ifac.org/system/files/downloads/a018-2010-iaasb-handbook-isa-320.pdf | F10: ISA 320
B11: https://www.ifac.org/system/files/downloads/a021-2010-iaasb-handbook-isa-450.pdf | F11: ISA 450
B12: Procedimentos efetuados:
B13: Obtivemos os possíveis benchmarks para avaliarmos o mais adequado a ser utilizado para cálculo da materialidade.
B14: Evidenciamos a nossa avaliação quanto a escolha do benchmark a ser utilizado.
B15: =CONCATENATE("Utilizamos como base o "&CONCATENATE(B19)&" registrada em"&" "&RIGHT(B4,10)) -> Utilizamos como base o Total de receitas da S3 Saude registrada em 31/12/2023
B16: Confrontamos a nossa expectativa com o orçamento da entidade e calculamos a materialidade com base na menor expectativa.
B19: =CONCATENATE('% Benchmark'!B51&" "&"da "&RIGHT(B2,50)) -> Total de receitas da S3 Saude
K20: g
B21: Valor da Demonstração Financeira | D21: =CONCATENATE("Periodo do Planejamento - Real"&" "&LEFT(RIGHT(B4,10),8)&RIGHT(B4,2)-1) -> Periodo do Planejamento - Real 31/12/2022 | G21: =CONCATENATE("Período do planejamento - Real"&" "&RIGHT(B4,10)) -> Período do planejamento - Real 31/12/2023 | K21: =CONCATENATE("∆ % Dez/"&""&RIGHT(B4,2)-1)&"- Dez/"&""&RIGHT(B4,2) -> ∆ % Dez/22- Dez/23
B22: Total de receitas | D22: 1402695.6 | F22: f | G22: 1.5025207e+09 | I22: ü | K22: =IFERROR((G22/D22-1),0) -> 1070.1666
B23: Compensation | C23: Compensation | D23: 0 | F23: f | G23: 0 | I23: ü | K23: =IFERROR((G23/D23-1),0) -> 0
B24: Basis for the calculation | D24: =D22-D23 -> 1402695.6 | F24: f | G24: =G22-G23 -> 1.5025207e+09 | I24: g | K24: =IFERROR((G24/D24-1),0) -> 1070.1666
B25: Materiality | D25: =D24*$E$27 -> 17561.749 | F25: f | G25: =G24*$E$27 -> 18811559 | I25: g | K25: =IFERROR((G25/D25-1),0) -> 1070.1666
B27: Materiality (M) | E27: ='% Benchmark'!C51 -> 0.01252 | G27: =G25 -> 18811559 | I27: g | K27: 19000000 | M27: d
B29: Performance Materiality (PM) | E29: ='% Benchmark'!C63 -> 0.57502 | G29: =G27*E29 -> 10817023 | I29: g | K29: 11000000 | M29: d
B31: AMPT | E31: ='% Benchmark'!D51 -> 0.03602 | G31: =G27*E31 -> 677592.35 | I31: g | K31: 700000 | M31: d
B35: Nota geral
B36: =CONCATENATE("A entidade se enquadra nos critérios estabelecidos pelo NBC TA 320 (R1) [DOU 05/09/16] - Materialidade no Planejamento e na Execução da Auditoria - [ISA 320], e optamos por adotar para calculo da materialidade o"&" "&'% Benchmark'!B51&" como benchmark.") -> A entidade se enquadra nos critérios estabelecidos pelo NBC TA 320 (R1) [DOU 05/09/16] - Materialidade no Planejamento e na Execução da Auditoria - [ISA 320], e optamos por adotar para calculo da materialidade o Total de receitas como benchmark.
B38: Entendemos manter uma postura conservadora pois é o primeiro ano que auditamos a entidade. É uma entidade que nunca foi auditada e o foco da Auditoria da entidade está verificar como as despesas estão sendo realizadas e se estão de acordo com o objeto social da entidade além das demais obrigações de uma auditoria.
B42: Tickmarks
A43: ü | B43: Conforme balancete do Exercício
A44: f | B44: Conforme balancete do Exercício anterior
A45: g | B45: Calculado pela VORCON.
A46: d | B46: Materialidade Ajustada

Sheet % Benchmark
B6: NBC TA 320 (R1) [DOU 05/09/16] - Materialidade no Planejamento e na Execução da Auditoria - [ISA 320]
B7: 9. Para fins das normas de auditoria, materialidade para execução da auditoria significa o valor ou valores fixados pelo auditor, inferiores ao considerado relevante para as demonstrações contábeis como um todo, para adequadamente reduzir a um nível baixo a probabilidade de que as distorções não corrigidas e não detectadas em conjunto, excedam a materialidade para as demonstrações contábeis como um todo. Se aplicável, materialidade para execução da auditoria refere-se, também, ao valor ou valores fixados pelo auditor inferiores ao nível ou níveis de materialidade para classes específicas de transações, saldos contábeis e divulgações.
B8: - for profit-oriented entities, profit or loss before tax from continuing operations is often used as the benchmark [Source: ISA 320.A4]
B9: - for not-for-profit entities, an appropriate benchmark may be total assets or total expenses
B12: Determinação do Benchmark
B14: Benchmarks | C14: % Mínimo | D14: % Máximo
A15: (a) | B15: Lucro antes dos impostos | C15: 0.03 | D15: 0.1
A16: (b) | B16: Total de receitas | C16: 0.005 | D16: 0.03
A17: (c) | B17: Total de ativos | C17: 0.005 | D17: 0.03
A18: (d) | B18: Patrimônio líquido | C18: 0.03 | D18: 0.1
A19: (e) | B19: Total de despesas | C19: 0.005 | D19: 0.03 | K19: M
B22: Definição do PM e AMPT | C22: PARÁGRAFOS NBC TA 320 (R1)
B24: Podemos utilizar a materialidade para das demonstrações financeiras como um valor que norteia a determinação do cálculo da PM. A PM não pode exceder 75% da M como um todo e varia de 50% a 75% conforme nossa avaliação de risco. | C24: [Fonte: ISA 320.A7 / NBC TA 320.A8] VORCON AUDIT METODOLOGY V.A.M.
B26: The AMPT ordinarily falls between 3 to 5 percent of materiality for the financial statements as a whole. | C26: [Fonte: ISA 320.A7 / NBC TA 320.A8]
B31: Critérios a considerar para determinação da porcentagem aplicada ao benchmark (Materiality e AMPT) | C31: Resposta | D31: Pontuação | E31: Avaliação de Risco
A32: (1). | B32: Entidade aberta ou de interesse público? A Entidade possui intenção de negociar em bolsa? | C32: N | D32: =IF(C32="S",1,0) -> 0
A33: (2). | B33: Dívida negociada publicamente? Contratos de empréstimo sensíveis a resultados operacionais? | C33: S | D33: =IF(C33="S",1,0) -> 1
A34: (3). | B34: A entidade opera em um ambiente de negócios volátil? A entidade opera em localizações que estão sujeitas à instabilidade política? | C34: S | D34: =IF(C34="S",1,0) -> 1
A35: (4). | B35: A entidade possui operações complexas e/ou processos de negócios diversos? | C35: S | D35: =IF(C35="S",1,0) -> 1
A36: (5). | B36: Operam em uma indústria altamente regulada? | C36: S | D36: =IF(C36="S",1,0) -> 1
A37: (6). | B37: Venda recente ou esperada da Entidade? | C37: N | D37: =IF(C37="S",1,0) -> 0
D38: =SUM(D32:D37) -> 4 | E38: =_xlfn.XLOOKUP(D38,$C$41:$C$47,$B$41:$B$47) -> Médio/Alto
B40: Classificação de Risco para PM e AMPT | C40: Pontuação
B41: Muito Baixo | C41: 0
B42: Baixo | C42: 1
B43: Médio/Baixo | C43: 2
B44: Médio | C44: 3
B45: Médio/Alto | C45: 4
B46: Alto | C46: 5
B47: Crítico | C47: 6
B50: Critério utilizado | C50: M | D50: AMPT
B51: Total de receitas | C51: =_xlfn.XLOOKUP(B51,'Tabela Benckmarking'!$B$60:$B$64,'Tabela Benckmarking'!$E$60:$E$64) -> 0.01252 | D51: =_xlfn.XLOOKUP(B51,'Tabela Benckmarking'!$B$60:$B$64,'Tabela Benckmarking'!$G$60:$G$64) -> 0.03602
B53: Critérios a considerar para determinação da porcentagem aplicada ao performance materiality (PM) | C53: Resposta | D53: Pontuação | E53: Avaliação de Risco
A54: (1). | B54: Um ambiente de controle fraco; | C54: S | D54: =IF(C54="S",1,0) -> 1
A55: (2). | B55: Uma entidade com um histórico de fraqueza material e/ou deficiências de controles; | C55: S | D55: =IF(C55="S",1,0) -> 1
A56: (3). | B56: Rotatividade excessiva nas alta administração; | C56: N | D56: =IF(C56="S",1,0) -> 0
A57: (4). | B57: Entidade com histórico de excessivos erros em auditorias anteriores | C57: N | D57: =IF(C57="S",1,0) -> 0
A58: (5). | B58: Entidade com questões financeiras mais complexas e estimativas significativas; | C58: S | D58: =IF(C58="S",1,0) -> 1
A59: (6). | B59: Entidade que opera em várias localidades; | C59: S | D59: =IF(C59="S",1,0) -> 1
D60: =SUM(D54:D59) -> 4 | E60: =_xlfn.XLOOKUP(D60,$C$41:$C$47,$B$41:$B$47) -> Médio/Alto
...

Sheet Tabela Benckmarking
B8: Objetivos:
B9: Dependendo dos Critérios a considerar para determinação da porcentagem aplicada ao benchmark (Materiality e AMPT), direcionamos uma pontuação e criamos um critério de avaliação de risco.
B11: Observações:
B12: Quanto maior a Materiality, menor a chance de mais testes, logo, quanto maior o Risco, menor será a Materiality.
B13: Se nosso grau de avaliação de Risco chegar a 6 (Crítico) pode ser necessário, por julgamento profissional, avaliar um % inferior.
B14: Os cálculos de M e AMPT envolvem uma média entre os máximos e mínimos de acordo com sua pontuação na classificação de risco.
B16: Banckmark | C16: Pontuação | D16: M | F16: Banckmark | G16: Pontuação | H16: M | J16: Banckmark | K16: Pontuação | L16: M | N16: Banckmark | O16: Pontuação | P16: M | R16: Banckmark | S16: Pontuação | T16: M
B17: =B26 -> Lucro antes dos impostos | C17: ='% Benchmark'!$D38 -> 4 | D17: =AVERAGE(_xlfn.XLOOKUP($C17,$B$28:$B$41,$C$28:$C$41),_xlfn.XLOOKUP($C17,$B$28:$B$41,$D$28:$D$41))/100 -> 0.0446025 | F17: =F26 -> Total de receitas | G17: ='% Benchmark'!$D38 -> 4 | H17: =AVERAGE(_xlfn.XLOOKUP(G17,F$28:F$34,G$28:G$34),_xlfn.XLOOKUP(G17,F$28:F$34,H$28:H$34))/100 -> 0.01252 | J17: =J26 -> Total de ativos | K17: ='% Benchmark'!$D38 -> 4 | L17: =AVERAGE(_xlfn.XLOOKUP(K17,J$28:J$34,K$28:K$34),_xlfn.XLOOKUP(K17,J$28:J$34,L$28:L$34))/100 -> 0.01252 | N17: =N26 -> Patrimônio líquido | O17: ='% Benchmark'!$D38 -> 4 | P17: =AVERAGE(_xlfn.XLOOKUP($O17,$N$28:$N$41,$O$28:$O$41),_xlfn.XLOOKUP($O17,$N$28:$N$41,$P$28:$P$41))/100 -> 0.0446025 | R17: =R26 -> Total de despesas | S17: ='% Benchmark'!$D38 -> 4 | T17: =AVERAGE(_xlfn.XLOOKUP(S17,R$28:R$34,S$28:S$34),_xlfn.XLOOKUP(S17,R$28:R$34,T$28:T$34))/100 -> 0.01252
B18: Banckmark | C18: Pontuação | D18: AMPT | F18: Banckmark | G18: Pontuação | H18: AMPT | J18: Banckmark | K18: Pontuação | L18: AMPT | N18: Banckmark | O18: Pontuação | P18: AMPT | R18: Banckmark | S18: Pontuação | T18: AMPT
B19: =B17 -> Lucro antes dos impostos | C19: =C17 -> 4 | D19: =AVERAGE(_xlfn.XLOOKUP(C19,$B$49:$B$55,$C$49:$C$55),_xlfn.XLOOKUP(C19,$B$49:$B$55,$D$49:$D$55))/100 -> 0.03602 | F19: =F17 -> Total de receitas | G19: ='% Benchmark'!D38 -> 4 | H19: =AVERAGE(_xlfn.XLOOKUP(G19,$B$49:$B$55,$C$49:$C$55),_xlfn.XLOOKUP(G19,$B$49:$B$55,$D$49:$D$55))/100 -> 0.03602 | J19: =J17 -> Total de ativos | K19: ='% Benchmark'!H38 -> 0 | L19: =AVERAGE(_xlfn.XLOOKUP(K19,$B$49:$B$55,$C$49:$C$55),_xlfn.XLOOKUP(K19,$B$49:$B$55,$D$49:$D$55))/100 -> 0.05 | N19: =N17 -> Patrimônio líquido | O19: =O17 -> 4 | P19: =AVERAGE(_xlfn.XLOOKUP(O19,$B$49:$B$55,$C$49:$C$55),_xlfn.XLOOKUP(O19,$B$49:$B$55,$D$49:$D$55))/100 -> 0.03602 | R19: =R17 -> Total de despesas | S19: ='% Benchmark'!P38 -> 0 | T19: =AVERAGE(_xlfn.XLOOKUP(S19,$B$49:$B$55,$C$49:$C$55),_xlfn.XLOOKUP(S19,$B$49:$B$55,$D$49:$D$55))/100 -> 0.05
B20: PM | C20: Pontuação | D20: PM | F20: PM | G20: Pontuação | H20: PM | J20: PM | K20: Pontuação | L20: PM | N20: PM | O20: Pontuação | P20: PM | R20: PM | S20: Pontuação | T20: PM
B21: =B17 -> Lucro antes dos impostos | C21: ='% Benchmark'!$D60 -> 4 | D21: =AVERAGE(_xlfn.XLOOKUP(C21,$F$49:$F$55,$G$49:$G$55),_xlfn.XLOOKUP(C21,$F$49:$F$55,$H$49:$H$55))/100 -> 0.57502 | F21: =F17 -> Total de receitas | G21: ='% Benchmark'!$D60 -> 4 | H21: =AVERAGE(_xlfn.XLOOKUP(G21,$F$49:$F$55,$G$49:$G$55),_xlfn.XLOOKUP(G21,$F$49:$F$55,$H$49:$H$55))/100 -> 0.57502 | J21: =J17 -> Total de ativos | K21: ='% Benchmark'!$D60 -> 4 | L21: =AVERAGE(_xlfn.XLOOKUP(K21,$F$49:$F$55,$G$49:$G$55),_xlfn.XLOOKUP(K21,$F$49:$F$55,$H$49:$H$55))/100 -> 0.57502 | N21: =N17 -> Patrimônio líquido | O21: ='% Benchmark'!$D60 -> 4 | P21: =AVERAGE(_xlfn.XLOOKUP(O21,$F$49:$F$55,$G$49:$G$55),_xlfn.XLOOKUP(O21,$F$49:$F$55,$H$49:$H$55))/100 -> 0.57502 | R21: =R17 -> Total de despesas | S21: ='% Benchmark'!$D60 -> 4 | T21: =AVERAGE(_xlfn.XLOOKUP(S21,$F$49:$F$55,$G$49:$G$55),_xlfn.XLOOKUP(S21,$F$49:$F$55,$H$49:$H$55))/100 -> 0.57502
C24: Fator | D24: 0.5721 | G24: Fator | H24: 0.488 | K24: Fator | L24: 0.488 | O24: Fator | P24: 0.5721 | S24: Fator | T24: 0.488
B25: Benchmarks | C25: % Mínimo | D25: % Máximo | F25: Benchmarks | G25: % Mínimo | H25: % Máximo | J25: Benchmarks | K25: % Mínimo | L25: % Máximo | N25: Benchmarks | O25: % Mínimo | P25: % Máximo | R25: Benchmarks | S25: % Mínimo | T25: % Máximo
B26: Lucro antes dos impostos | C26: 0.03 | D26: 0.1 | F26: Total de receitas | G26: 0.005 | H26: 0.03 | J26: Total de ativos | K26: 0.005 | L26: 0.03 | N26: Patrimônio líquido | O26: 0.03 | P26: 0.1 | R26: Total de despesas | S26: 0.005 | T26: 0.03
B27: Pontuação de Risco | C27: % Mínimo | D27: % Máximo | F27: Pontuação de Risco | G27: % Mínimo | H27: % Máximo | J27: Pontuação de Risco | K27: % Mínimo | L27: % Máximo | N27: Pontuação de Risco | O27: % Mínimo | P27: % Máximo | R27: Pontuação de Risco | S27: % Mínimo | T27: % Máximo
B28: 6 | C28: 3 | D28: 3 | F28: 6 | G28: 0.5 | H28: 0.5 | J28: 6 | K28: 0.5 | L28: 0.5 | N28: 6 | O28: 3 | P28: 3 | R28: 6 | S28: 0.5 | T28: 0.5
B29: 5 | C29: =D28+0.01 -> 3.01 | D29: =C29+$D$24 -> 3.5821 | F29: 5 | G29: 0.51 | H29: =G29+$H$24 -> 0.998 | J29: 5 | K29: 0.51 | L29: =K29+$L$24 -> 0.998 | N29: 5 | O29: =P28+0.01 -> 3.01 | P29: =O29+$P$24 -> 3.5821 | R29: 5 | S29: 0.51 | T29: =S29+$T$24 -> 0.998
B30: 5 | C30: =D29+0.01 -> 3.5921 | D30: =C30+$D$24 -> 4.1642 | F30: 4 | G30: =H29+0.01 -> 1.008 | H30: =G30+$H$24 -> 1.496 | J30: 4 | K30: =L29+0.01 -> 1.008 | L30: =K30+$L$24 -> 1.496 | N30: 5 | O30: =P29+0.01 -> 3.5921 | P30: =O30+$P$24 -> 4.1642 | R30: 4 | S30: =T29+0.01 -> 1.008 | T30: =S30+$T$24 -> 1.496
B31: 4 | C31: =D30+0.01 -> 4.1742 | D31: =C31+$D$24 -> 4.7463 | F31: 3 | G31: =H30+0.01 -> 1.506 | H31: =G31+$H$24 -> 1.994 | J31: 3 | K31: =L30+0.01 -> 1.506 | L31: =K31+$L$24 -> 1.994 | N31: 4 | O31: =P30+0.01 -> 4.1742 | P31: =O31+$P$24 -> 4.7463 | R31: 3 | S31: =T30+0.01 -> 1.506 | T31: =S31+$T$24 -> 1.994
B32: 4 | C32: =D31+0.01 -> 4.7563 | D32: =C32+$D$24 -> 5.3284 | F32: 2 | G32: =H31+0.01 -> 2.004 | H32: =G32+$H$24 -> 2.492 | J32: 2 | K32: =L31+0.01 -> 2.004 | L32: =K32+$L$24 -> 2.492 | N32: 4 | O32: =P31+0.01 -> 4.7563 | P32: =O32+$P$24 -> 5.3284 | R32: 2 | S32: =T31+0.01 -> 2.004 | T32: =S32+$T$24 -> 2.492
B33: 3 | C33: =D32+0.01 -> 5.3384 | D33: =C33+$D$24 -> 5.9105 | F33: 1 | G33: =H32+0.01 -> 2.502 | H33: =G33+$H$24 -> 2.99 | J33: 1 | K33: =L32+0.01 -> 2.502 | L33: =K33+$L$24 -> 2.99 | N33: 3 | O33: =P32+0.01 -> 5.3384 | P33: =O33+$P$24 -> 5.9105 | R33: 1 | S33: =T32+0.01 -> 2.502 | T33: =S33+$T$24 -> 2.99
B34: 3 | C34: =D33+0.01 -> 5.9205 | D34: =C34+$D$24 -> 6.4926 | F34: 0 | G34: 3 | H34: 3 | J34: 0 | K34: 3 | L34: 3 | N34: 3 | O34: =P33+0.01 -> 5.9205 | P34: =O34+$P$24 -> 6.4926 | R34: 0 | S34: 3 | T34: 3
B35: 2 | C35: =D34+0.01 -> 6.5026 | D35: =C35+$D$24 -> 7.0747 | N35: 2 | O35: =P34+0.01 -> 6.5026 | P35: =O35+$P$24 -> 7.0747
B36: 2 | C36: =D35+0.01 -> 7.0847 | D36: =C36+$D$24 -> 7.6568 | N36: 2 | O36: =P35+0.01 -> 7.0847 | P36: =O36+$P$24 -> 7.6568
B37: 2 | C37: =D36+0.01 -> 7.6668 | D37: =C37+$D$24 -> 8.2389 | N37: 2 | O37: =P36+0.01 -> 7.6668 | P37: =O37+$P$24 -> 8.2389
B38: 1 | C38: =D37+0.01 -> 8.2489 | D38: =C38+$D$24 -> 8.821 | N38: 1 | O38: =P37+0.01 -> 8.2489 | P38: =O38+$P$24 -> 8.821
B39: 1 | C39: =D38+0.01 -> 8.831 | D39: =C39+$D$24 -> 9.4031 | N39: 1 | O39: =P38+0.01 -> 8.831 | P39: =O39+$P$24 -> 9.4031
B40: 1 | C40: =D39+0.01 -> 9.4131 | D40: =C40+$D$24 -> 9.9852 | N40: 1 | O40: =P39+0.01 -> 9.4131 | P40: =O40+$P$24 -> 9.9852
B41: 0 | C41: 10 | D41: =C41 -> 10 | N41: 0 | O41: 10 | P41: =O41 -> 10
B45: AMPT | C45: Fator | D45: 0.388 | F45: PM | G45: Fator | H45: 4.988
B46: Benchmarks | C46: % Mínimo | D46: % Máximo | F46: Benchmarks | G46: % Mínimo | H46: % Máximo
B47: AMPT | C47: 0.03 | D47: 0.05 | F47: PM | G47: 0.5 | H47: 0.75
B48: Pontuação de Risco | C48: % Mínimo | D48: % Máximo | F48: Pontuação de Risco | G48: % Mínimo | H48: % Máximo
B49: 6 | C49: 3 | D49: 3 | F49: 6 | G49: 50 | H49: 50
B50: 5 | C50: =D49+0.01 -> 3.01 | D50: =C50+$D$45 -> 3.398 | F50: 5 | G50: =H49+0.01 -> 50.01 | H50: =G50+$H$45 -> 54.998
B51: 4 | C51: =D50+0.01 -> 3.408 | D51: =C51+$D$45 -> 3.796 | F51: 4 | G51: =H50+0.01 -> 55.008 | H51: =G51+$H$45 -> 59.996
B52: 3 | C52: =D51+0.01 -> 3.806 | D52: =C52+$D$45 -> 4.194 | F52: 3 | G52: =H51+0.01 -> 60.006 | H52: =G52+$H$45 -> 64.994
B53: 2 | C53: =D52+0.01 -> 4.204 | D53: =C53+$D$45 -> 4.592 | F53: 2 | G53: =H52+0.01 -> 65.004 | H53: =G53+$H$45 -> 69.992
B54: 1 | C54: =D53+0.01 -> 4.602 | D54: =C54+$D$45 -> 4.99 | F54: 1 | G54: =H53+0.01 -> 70.002 | H54: =G54+$H$45 -> 74.99
...

Sheet Sheet1
