Workbook
Name _Hlk102822595: 'BASE DE PONTOS V+'!#REF!
Name _Hlk102822605: 'BASE DE PONTOS V+'!#REF!
Name _Hlk44932008: 'Matriz de Risco'!$C$9
Name _Hlk44932008: 'RESUMO DE PONTOS'!#REF!
Name _Hlk44932008: 'RESUMO DE PONTOS Original'!$C$8
Name _Hlk44932282: 'Matriz de Risco'!$C$13
Name _Hlk44933547: 'Matriz de Risco'!$C$17
Name _Hlk44933737: 'Matriz de Risco'!$C$18
Name _Toc54348655: 'BASE DA MATRIZ DE RISCOS'!$C$19
Name _Toc54348656: 'BASE DA MATRIZ DE RISCOS'!$C$20
Name _Toc54348657: 'BASE DA MATRIZ DE RISCOS'!$C$37
Name _Toc54348658: 'BASE DA MATRIZ DE RISCOS'!$C$46
Name _Toc54348659: 'BASE DA MATRIZ DE RISCOS'!$C$75
Name _Toc54348660: 'BASE DA MATRIZ DE RISCOS'!$C$76
Name _Toc54348662: 'BASE DA MATRIZ DE RISCOS'!$C$127
Name _Toc70060767: TESTES!#REF!
Name _Toc70060768: TESTES!#REF!
Name _Toc70060769: TESTES!#REF!
Name _Toc70060770: TESTES!#REF!
Name _Toc70060771: TESTES!#REF!
Name _Toc70060772: TESTES!#REF!
Name _Toc70060773: TESTES!#REF!
Name _Toc70060774: TESTES!#REF!
Name _Toc70060775: TESTES!#REF!
Name _Toc70060776: TESTES!#REF!
Name _Toc70060777: TESTES!#REF!
Name _Toc70060778: TESTES!#REF!
Name _Toc70060779: TESTES!#REF!
Name _Toc70060780: TESTES!#REF!
Name _Toc70060781: TESTES!#REF!
Name _Toc70060782: TESTES!#REF!
Name _Toc70060783: TESTES!#REF!
Name _Toc70060784: TESTES!#REF!
Name _Toc70060785: TESTES!#REF!
Name _Toc70060786: TESTES!#REF!
Name _Toc70060787: TESTES!#REF!
Name _Toc70060788: TESTES!#REF!
Name _Toc70060789: TESTES!#REF!
Name _Toc70060790: TESTES!#REF!
Name _Toc70060791: TESTES!#REF!
Name _Toc70060792: TESTES!#REF!
Name _Toc70060793: TESTES!#REF!
Name _Toc70060794: TESTES!#REF!
Name _Toc70060795: TESTES!#REF!
Name _Toc70060796: TESTES!#REF!
Name _Toc70060797: TESTES!#REF!
Name _Toc70060798: TESTES!#REF!
Name _Toc70060799: TESTES!#REF!
Name _Toc70060800: TESTES!#REF!
Name _Toc70060801: TESTES!#REF!
Name _Toc70060802: TESTES!#REF!
Name _Toc70060803: TESTES!#REF!
Name _Toc70060804: TESTES!#REF!
Name _Toc70060805: TESTES!#REF!
Name _Toc70060806: TESTES!#REF!
Name _Toc70060807: TESTES!#REF!
Name _Toc70060808: TESTES!#REF!
Name _Toc70060809: TESTES!#REF!
Name _Toc70060810: TESTES!#REF!
Name _Toc70060811: TESTES!#REF!

Sheet TESTES
B2: Condomínio Mar de Itapuã
B3: Testes e Procedimentos da Auditoira Condominial
B4: Data base: 01/01/2021 à 31/12/2021
B6: Etapas | C6: Análise do Contrato - Auditoria conforme a NBC TA 800 | D6: Responsável | E6: Código Vorcon | F6: Cliente | G6: Testes e Procedimentos de Auditoria realizados | H6: Código do Teste | I6: Status testes | J6: Responsável | K6: Pedido de análise | L6: Descrição no Pedido de Análise | M6: Status pedido de análise | N6: Observações | P6: Simbolo | Q6: Tipo | R6: Conclusão
B7: Planejamento | E7: 01.1.1 | F7: CRP | G7: Confirmação de Independência | H7: 01.1.1 - CRP - Confirmação de Independência | I7: a | J7: Isaias | K7: N/A | M7: x | P7: a | Q7: OK | R7: =COUNTIFS(I7:I54,"a")/COUNTA(H7:H54) -> 0.41666667
B8: Planejamento | E8: 01.1.2 | F8: CRP | G8: Pedido de Análise | H8: 01.1.2 - CRP - Pedido de Análise | I8: a | J8: Isaias | K8: N/A | M8: x | P8: x | Q8: Não Aplicável | R8: =COUNTIFS(I7:I54,"x")/COUNTA(H7:H54) -> 0.27083333
B9: Planejamento | E9: 01.1.3 | F9: CRP | G9: Entrevista para entendimento dos controles internos do condomínio (Inquiries) | H9: 01.1.3 - CRP - Entrevista para entendimento dos controles internos do condomínio | I9: a | J9: Isaias | K9: N/A | M9: x | P9: r | Q9: Pendente | R9: =COUNTIFS(I7:I54,"")/COUNTA(H7:H54) -> 0.10416667
B10: Planejamento | E10: 01.1.4 | F10: CRP | G10: Cálculo da Materialidade | H10: 01.1.4 - CRP - Cálculo da Materialidade | I10: a | J10: Isaias | K10: Demonstrativos Financeiros - Relatório (01/01/2019 à 31/12/2021) | M10: a | P10: q | Q10: Em Andamento | R10: =COUNTIFS(I9:I56,"q")/COUNTA(H9:H56) -> 0.02173913
B11: Planejamento | E11: 01.1.5 | F11: CRP | G11: Follow Up CCI | H11: 01.1.5 - CRP - Follow Up CCI | I11: a | J11: Renata | K11: Relatório de auditoria anterior (2018) | M11: a
B12: Preparação | E12: 01.1.6 | F12: CRP | G12: Voucher documental | H12: 01.1.6 - CRP - Voucher documental | I12: a | J12: Time Vorcon | K12: Balancetes 100% | M12: a
B13: Preparação | E13: 01.1.7 | F13: CRP | G13: Constituição e operação do Condomínio | H13: 01.1.7 - CRP - Constituição e operação do Condomínio | I13: a | J13: David | K13: Convenção + Regimento Interno | M13: a
B14: Preparação | E14: 01.1.8 | F14: CRP | G14: Resumo Regimento | H14: 01.1.8 - CRP - Resumo Regimento | I14: a | J14: Renata | K14: Regimento Interno | M14: a
B15: Preparação | E15: 01.1.9 | F15: CRP | G15: Resumo Convenção | H15: 01.1.9 - CRP - Resumo Convenção | I15: a | J15: Renata | K15: Convenção | M15: a
B16: Preparação | E16: 01.1.10 | F16: CRP | G16: Resumo do Manual de Obrigações Trabalhistas | H16: 01.1.10 - CRP - Resumo do Manual de Obrigações Trabalhistas | I16: x | J16: - | K16: N/A | M16: x
B17: Preparação | E17: 01.1.11 | F17: CRP | G17: Resumo do Manual Operacional de Receitas | H17: 01.1.11 - CRP - Resumo do Manual Operacional de Receitas | I17: x | J17: - | K17: N/A | M17: x
B18: Preparação | E18: 01.1.12 | F18: CRP | G18: Resumo do Manual de Contratação | H18: 01.1.12 - CRP - Resumo do Manual de Contratação | I18: x | J18: - | K18: N/A | M18: x
B19: Preparação | E19: 01.1.13 | F19: CRP | G19: Carta de Representação de Atas | H19: 01.1.13 - CRP - Carta de Representação de Atas | I19: a | J19: Isaias | K19: N/A | M19: a
B20: Preparação | E20: 01.1.14 | F20: CRP | G20: Resumo Atas | H20: 01.1.14 - CRP - Resumo Atas | I20: a | J20: Renata | K20: Assinatura da Carta de Representação de Atas | M20: a
B21: Preparação | E21: 01.1.15 | F21: CRP | G21: Teste de voucher (inspeção das guias e confronto dos saldos demonstrativos) | H21: 01.1.15 - CRP - Teste de voucher (inspeção das guias e confronto dos saldos demonstrativos) | I21: r | J21: Isaias | K21: Balancetes 100% | M21: a
B22: Preparação | E22: 01.1.16 | F22: CRP | G22: Consolidação dos saldos dos demonstrativos financeiro + Voucher Documental | H22: 01.1.16 - CRP - Consolidação dos saldos dos demonstrativos financeiro + Voucher Documental | I22: a | J22: Time Vorcon | K22: Demonstrativo Financeiros + Balancetes | M22: a
B23: Execução | E23: 01.1.17 | F23: CRP | G23: Emitir Cartas de Circularização aos Bancos | H23: 01.1.17 - CRP - Emitir Cartas de Circularização aos Bancos | I23: x | K23: N/A | M23: x
B24: Execução | E24: 01.1.18 | F24: CRP | G24: Carta de Representação de Instituições Financeiras | H24: 01.1.18 - CRP - Carta de Representação de Instituições Financeiras | I24: a | J24: Isaias | K24: N/A | M24: a
B25: Execução | E25: 01.1.19 | F25: CRP | G25: Validação da Carta de Representação de Instituições Financeiras | H25: 01.1.19 - CRP - Validação da Carta de Representação de Instituições Financeiras | I25: r | J25: Renata | K25: Assinatura da Carta de Representação de Instituição Financeira | M25: a
B26: Execução | E26: 01.1.20 | F26: CRP | G26: Demonstrativo Financeiro + voucher nos extratos | H26: 01.1.20 - CRP - Demonstrativo Financeiro + voucher nos extratos | I26: q | J26: Isaias | K26: Demonstrativo Financeiros + Extratos | M26: a
B27: Execução | E27: 01.1.21 | F27: CRP | G27: Conciliação Bancária + Elaboração dos quadros dos Demonstrativos Financeiros | H27: 01.1.21 - CRP - Conciliação Bancária + Elaboração dos quadros dos Demonstrativos Financeiros | I27: a | J27: Isaias | K27: Demonstrativo Financeiros + Extratos + Balancetes | M27: a
B28: Execução | E28: 01.1.22 | F28: CRP | G28: Orçado X Realizado | H28: 01.1.22 - CRP - Orçado X Realizado | I28: x | J28: - | K28: Planejamento Orçamentário + Orçado x Realizado | M28: x
B29: Execução | E29: 01.1.23 | F29: CRP | G29: Revisão analitica de demonstrativos | H29: 01.1.23 - CRP - Revisão analitica de demonstrativos | I29: a | J29: Renata | K29: Demonstrativos Financeiros | M29: a
B30: Execução | E30: 01.1.23.1 | F30: CRP | G30: Revisão do Fundo de Reserva | H30: 01.1.23.1 - CRP - Revisão do Fundo de Reserva | I30: r | J30: Isaias | K30: Relatório Analítico do Fundo de Reserva (Está nos Extratos) | M30: a
B31: Execução | E31: 01.1.24 | F31: CRP | G31: Walkthrough de Receita | H31: 01.1.24 - CRP - Walkthrough de Receita | I31: x | J31: - | K31: N/A | M31: x
B32: Execução | E32: 01.1.25 | F32: CRP | G32: TOD + TOE de Receita | H32: 01.1.25 - CRP - TOD + TOE de Receita | I32: x | J32: - | K32: N/A | M32: x
B33: Execução | E33: 01.1.26 | F33: CRP | G33: Validação de Inadimplentes | H33: 01.1.26 - CRP - Validação de Inadimplentes | I33: a | J33: Isaias | K33: Inadimplentes | M33: a
B34: Execução | E34: 01.1.27 | F34: CRP | G34: Seguros | H34: 01.1.27 - CRP - Seguros | I34: r | J34: David | K34: Seguros | M34: a
B35: Execução | E35: 01.1.28 | F35: CRP | G35: Carta de Representação de Prestadores de Serviços (Detalhar os principais) | H35: 01.1.28 - CRP - Carta de Representação de Prestadores de Serviços (Detalhar os principais) | I35: a | J35: Isaias | K35: N/A | M35: x
... B49: Execução | E49: 01.1.42 | F49: CRP | G49: Teste de Contingências + Circularização de assessor jurídico | H49: 01.1.42 - CRP - Teste de Contingências + Circularização de assessor jurídico | I49: r | J49: Renata | K49: Controle auxiliar da Provisões para Contingências (Analítico) + Assinatura da Carta de Representação de Assessores Jurídicos | M49: x
B50: Revisão | E50: 01.1.43 | F50: CRP | G50: Consolidação de pontos (baseado no novo modelo com matriz de risco.) | H50: 01.1.43 - CRP - Consolidação de pontos (baseado no novo modelo com matriz de risco.) | K50: N/A | M50: x
B51: Revisão | E51: 01.1.44 | F51: CRP | G51: Carta de Representação da Administração | H51: 01.1.44 - CRP - Carta de Representação da Administração | J51: Renata
B52: Revisão | E52: 01.1.45 | F52: CRP | G52: Minuta da Auditoria NBC TA 800 | H52: 01.1.45 - CRP - Minuta da Auditoria NBC TA 800 | J52: Isaias
B53: Revisão | E53: 01.1.46 | F53: CRP | G53: Minuta da Apresentação da Auditoria NBC TA 800 | H53: 01.1.46 - CRP - Minuta da Apresentação da Auditoria NBC TA 800 | J53: Isaias
B54: Revisão | E54: 01.1.47 | F54: CRP | G54: Relatório Final da Auditoria NBC TA 800 | H54: 01.1.47 - CRP - Relatório Final da Auditoria NBC TA 800 | J54: Isaias

Sheet OPNIÃO
B1: Condomínios
B2: APROVA | C2: RELATÓRIO COM OPINIÃO SEM RESSALVA | D2: O relatório sem ressalva é emitido quando o auditor está convencido sobre todos os aspectos relevantes dos assuntos tratados no item 4 deste Pronunciamento. O relatório do auditor independente deve expressar essa convicção de forma clara e objetiva. | E2: O relatório sem ressalva implica afirmação de que, em tendo havido alterações em princípios contábeis ou no método de sua aplicação, o fato e os efeitos dele decorrentes foram adequadamente determinados e revelados nas demonstrações contábeis e/ou nas notas explicativas. | F2: O auditor não deve emitir um relatório sem ressalva quando existirem quaisquer das circunstâncias seguintes, que, na sua opinião, tenham efeitos relevantes para as demonstrações contábeis.
B3: APROVA COM RESSALVA | C3: RELATÓRIO COM OPINIÃO COM RESSALVA | D3: O relatório com ressalva é emitido quando o auditor conclui que o efeito de qualquer discordância ou restrição na extensão de um trabalho não é de tal magnitude que requeira relatório adverso ou abstenção de opinião. | E3: O relatório com ressalva deve obedecer ao modelo do relatório sem ressalva, com a utilização das expressões "exceto por", "exceto quanto" ou "com exceção de", referindo-se aos efeitos do assunto objeto da ressalva. Não é aceitável nenhuma outra expressão na redação desse tipo de relatório.
B4: Não APROVA | C4: RELATÓRIO COM OPINIÃO ADVERSO | D4: O auditor deve emitir relatório adverso quando verificar que as demonstrações contábeis estão incorretas ou incompletas, em tal magnitude que impossibilite a emissão do relatório com ressalvas. | E4: Assim, relatório adverso é o que exprime a opinião de que as demonstrações contábeis não representam adequadamente a posição patrimonial e financeira, nem o resultado das operações, e/ou as mutações do patrimônio líquido, e/ou as origens e aplicações de recursos de acordo com os Princípios Fundamentais de Contabilidade. | F4: O auditor deve, portanto, emitir relatório adverso quando verificar efeitos que, em sua opinião, comprometam em tal magnitude das demonstrações contábeis examinadas a ponto de não ser suficiente a simples ressalva no relatório. Nessas circunstâncias, uma ressalva não é considerada apropriada, uma vez que o auditor possui informações suficientes para declarar que as demonstrações contábeis não estão adequadamente apresentadas.
B5: Não APROVA | C5: RELATÓRIO COM ABSTENÇÃO DE OPINIÃO | D5: O relatório com abstenção de opinião é emitido quando houver uma limitação significativa na extensão de seus exames que impossibilite o auditor expressar opinião sobre as demonstrações contábeis por não ter obtido comprovação suficiente para fundamentá-la. Abstenção de opinião por limitação da extensão | E5: Nos casos de limitações significativas, o auditor deve, no parágrafo da extensão, indicar claramente os procedimentos omitidos e suas circunstâncias ou fazer uma referência a um parágrafo intermediário específico do relatório que descreva tal limitação. Em quaisquer desses casos, em parágrafo final do relatório, o auditor deve mencionar claramente que o exame não foi suficiente para permitir emissão de opinião sobre as demonstrações contábeis tomadas em conjunto. A abstenção de opinião não elimina a responsabilidade do auditor em mencionar, no relatório, qualquer desvio relevante que possa influenciar a decisão do usuário dessas informações.
C7: Análise: Quando houver distorção relevante ou não identificação de evidências de que as demonstrações não apresentam distorções relevantes, o auditor deverá modificar sua opinião, entre: opinião com ressalva, adversa ou com abstenção de opinião.
C9: Nessas ocasiões, deve-se atentar para as seguintes palavras-chave:
C11: RELEVANTE + NÃO GENERALIZADA (com ou sem evidências): Opinião com ressalva;
C12: RELEVANTE + GENERALIZADA (com evidência): Opinião Adversa;
C13: RELEVANTE + GENERALIZADA (sem evidência): Abstenção de Opinião.
C15: Tipos de Opinião do Auditor
C17: 1. Opinião com ressalva
C19: O auditor deve expressar uma “Opinião com ressalva” quando:
C21: ele, tendo obtido evidência de auditoria apropriada e suficiente, conclui que as distorções, individualmente ou em conjunto, são relevantes, mas Não Generalizadas nas demonstrações contábeis; ou
C22: não é possível para ele obter evidência apropriada e suficiente de auditoria para fundamentar sua opinião, mas ele conclui que os possíveis efeitos de distorções não detectadas sobre as demonstrações contábeis, se houver, poderiam ser relevantes, MAS NÃO GENERALIZADOS.
C24: 2. Opinião adversa
C26: O auditor deve expressar uma “Opinião adversa” quando, tendo obtido evidência de auditoria apropriada e suficiente, conclui que as distorções, individualmente ou em conjunto, são RELEVANTES E GENERALIZADAS para as demonstrações contábeis.
... C30: O auditor deve se abster de expressar uma opinião quando não consegue obter evidência de auditoria apropriada e suficiente para fundamentar sua opinião e ele concluir que os possíveis efeitos de distorções não detectadas sobre as demonstrações contábeis, se houver, poderiam ser relevantes e generalizados.
D32: Natureza do assunto que gerou a modificação | E32: Julgamento do auditor sobre a disseminação de forma generalizada dos efeitos ou possíveis efeitos sobre as DFs
E33: Não Generalizado | F33: Generalizado
D34: DFs apresentam Distorsões Relevantes | E34: Opinião com Ressalva | F34: Opinião Adversa
D35: Impossibilidade de se Obter Evidência de Auditoria Apropriada e Suficiente | E35: Opinião com Ressalva | F35: Abstenção de Opinião

Sheet VELOCIMETRO
E1: =SUM(E2:E4) -> 0.5
D2: Não Aprova | E2: =50%-E3-E4 -> 0.125 | F2: =E2/$E$1 -> 0.25
D3: Aprova c/Ressalva | E3: 0.125 | F3: =E3/$E$1 -> 0.25
D4: Aprova | E4: 0.25 | F4: =E4/$E$1 -> 0.5
E5: 0.5
E6: Aprova | G6: Aprova c/ Ressalva | I6: Não Aprova | K6: Não Aprova
D7: Total de Pontos de baixo Impacto | E7: 0 | F7: =K23 -> 0.15384615 | G7: 2 | H7: =G7/$G$10 -> 0.14285714 | I7: 15 | J7: =I7/$I$10 -> 0.6 | K7: 15 | L7: =K7/$K$10 -> 0.42857143
D8: Ponteiro | E8: 5 | F8: 0.01 | G8: 5 | H8: =G8/$G$10 -> 0.35714286 | I8: 5 | J8: =I8/$I$10 -> 0.2 | K8: 10 | L8: =K8/$K$10 -> 0.28571429
D9: Total de Pontos de alto Impacto | E9: 15 | F9: =K21 -> 0.61538462 | G9: 7 | H9: =G9/$G$10 -> 0.5 | I9: 5 | J9: =I9/$I$10 -> 0.2 | K9: 10 | L9: =K9/$K$10 -> 0.28571429
E10: =SUM(E7:E9) -> 20 | F10: =SUM(F7:F9) -> 0.77923077 | G10: =SUM(G7:G9) -> 14 | H10: =SUM(H7:H9) -> 1 | I10: =SUM(I7:I9) -> 25 | J10: =SUM(J7:J9) -> 1 | K10: =SUM(K7:K9) -> 35 | L10: =SUM(L7:L9) -> 1
D12: 0% - 50% | E12: Se, pelo menos 75% dos pontos forem de baixo impacto e não houver nenhum ponto de Alto impacto crítico o bastante para reprovar as contas
D13: 51% - 75% | E13: Se a maioria dos pontos forem de Média e Baixo Impacto e houverem pouco s pontos de alto impacto ( pelo menos 75% forem de pontos de médio e baixo impacto e nos pontos de alto impacto não haver nenhum ponto crítico o bastante para reprovar as contas.
D14: 75% - 90% | E14: Se a maioria dos pontos forem de alto Impacto e houverem poucos pontos de baixo e médio impacto ( pelo menos 75% forem de pontos de alto impacto e nos pontos de alto impacto não haver nenhum ponto crítico o bastante para reprovar as contas.
D15: Crítico ( 100% ) | E15: Se houver algum ponto crítico o bastante que a auditoria julgue que seja impactante o suficiente para não permitir a aprovação das contas ou haja limitação de escopo que não permita que a auditoria seja realizada.
E20: Ponto | F20: Tipo | G20: Quantidade
E21: P01 | F21: ALTO | G21: 1 | I21: Alto | J21: =SUMIF($F$21:$F$46,$I21,$G$21:$G$46) -> 8 | K21: =J21/$J$24 -> 0.61538462
E22: P02 | F22: ALTO | G22: 1 | I22: Médio | J22: =SUMIF($F$21:$F$46,$I22,$G$21:$G$46) -> 3 | K22: =J22/$J$24 -> 0.23076923
E23: P03 | F23: ALTO | G23: 1 | I23: Baixo | J23: =SUMIF($F$21:$F$46,$I23,$G$21:$G$46) -> 2 | K23: =J23/$J$24 -> 0.15384615
E24: P04 | F24: ALTO | G24: 1 | J24: =SUM(J21:J23) -> 13 | K24: =SUM(K21:K23) -> 1
E25: P05 | F25: ALTO | G25: 1
E26: P06 | F26: ALTO | G26: 1
E27: P07 | F27: MÉDIO | G27: 1
E28: P08 | F28: BAIXO | G28: 1
E29: P09 | F29: ALTO | G29: 1
E30: P10 | F30: ALTO | G30: 1
E31: P11 | F31: BAIXO | G31: 1
E32: P12 | F32: MÉDIO | G32: 1
E33: P13 | F33: MÉDIO | G33: 1
E34: P14 | G34: 1
E35: P15 | G35: 1
E36: P16
E37: P17
E38: P18
E39: P19
E40: P20
E41: P21
E42: P22
E43: P23
E44: P24
E45: P25
...

Sheet BASE DE PONTOS V+
B2: Condomínio Mar de Itapuã
B3: BASE DE PONTOS V+
B4: Data base: 12/2021
B6: 2 | C6: 2 | H6: 7 | I6: 8 | J6: 8 | K6: 8 | M6: 8
B7: V+ | C7: Descrição Resumida | D7: Descrição | E7: Impacto Financeiro | F7: Riscos e Impactos | G7: Recomendação | H7: Tipo | I7: Tipo de Teste | J7: Julgamento | K7: Tipo de Teste | M7: Tipo de Teste
B8: V01 | C8: Pagamento sem nota fiscal | D8: Verificamos que ocorreram gastos sem a respectiva emissão de nota fiscal pelos fornecedores e prestadores de serviços. | E8: 47819.88 | F8: Pagamento sem os respectivos Fornecedores/Prestadores de serviços não é permitido pela legislação brasileira assim como Convenção e Regimento Interno do Condomínio podendo ser multado e/ou sofrer outras penalidades impostas pelo fisco. | G8: Sugerimos que seja solicitado aos respectivos Fornecedores/ Prestadores de serviços ou fornecedores a nota fiscal pelo fornecimento de material ou de prestação de serviço. | H8: Legal | I8: Voucher Documental | J8: Alto Impacto | L8: • 31/12/2021 • Recorrente ■ Vorcon Auditoria & Consultoria ■ 24/06/2022
B9: V02 | C9: Diferenças entre: Favorecido do documento X Beneficiário do pagamento | D9: O fornecedor apresentado no comprovante de pagamento não é o mesmo da Nota Fiscal. | E9: 516.77 | F9: Pagamentos realizados a fornecedores diferentes do da Nota Fiscal pode evidenciar pagamentos indevidos ou mesmo situações que levem a riscos de fraude. | G9: Sugerimos que seja solicitado aos respectivos prestadores de serviço ou fornecedores a nota fiscal pelo fornecimento de material ou de prestação de serviços. | H9: Legal | I9: Voucher Documental | J9: Baixo Impacto | L9: • 31/12/2021 • Recorrente ■ Vorcon Auditoria & Consultoria ■ 24/06/2022
B10: V03 | C10: Pagamentos realizados sem os respectivos comprovantes de pagamento anexados | D10: Verificamos que alguns pagamentos foram realizados sem que fossem anexados os respectivos comprovantes de pagamentos ou documentos equivalentes dando a respectiva quitação. | E10: 23309.37 | F10: Pagamento duplicado dos valores, ou caso haja a solicitação do comprovante de pagamento o Condomínio não os possua | G10: Sugerimos que sejam criados processos para que os comprovantes de pagamentos estejam anexados ao processo de pagamentos | H10: Financeiro | I10: Voucher Documental | J10: Alto Impacto | L10: • 31/12/2021 • Recorrente ■ Vorcon Auditoria & Consultoria ■ 24/06/2022
B11: V04 | C11: Negligência na gestão dos Documentos que compõe os Demonstrativos | D11: Verificamos que alguns comprovantes não estão sendo arquivados com os cuidados necessários, com isso alguns estão ilegíveis. | E11: 1087.39 | F11: Dificuldade na visualização dos gastos e impossibilidade e dúvidas quanto a possíveis consultas no futuro em função do estado dos documentos. | G11: Sugerimos que sejam criados processos para que os comprovantes sejam de responsabilidade do financeiro tirar cópia ou digitalizá-los assim que os receber. | H11: Operacional | I11: Voucher Documental | J11: Baixo Impacto | L11: • 31/12/2021 • Recorrente ■ Vorcon Auditoria & Consultoria ■ 24/06/2022
B12: V05 | C12: Pagamento de tarifa bancária. | D12: Verificamos que ocorreram pagamento de fornecedores e prestadores de serviços por meio de transferência bancária. | E12: 88.4 | F12: Pagamento de encargos financeiros que deveriam ser de responsabilidade dos Fornecedores/Prestadores de serviços | G12: Sugerimos que seja solicitado boleto para pagamento de todos os Fornecedores/Prestadores de serviços e em caso de negativa o valor dos encargos financeiros deve ser subtraído do pagamento. | H12: Financeiro | I12: Voucher Documental | J12: Baixo Impacto | L12: • 31/12/2021 • Recorrente ■ Vorcon Auditoria & Consultoria ■ 24/06/2022
B13: V06 | C13: Diferenças entre: Valor do comprovante de pagamento X Valor da documentação suporte. | D13: Verificamos que há diferença entre os valores apresentados, não justificada por parcelamento ou multa. | E13: 333.3 | F13: Possibilidade de pagamentos realizados com valores incorretos. | G13: Sugerimos que os pagamentos sejam realizados com os valores que constam no documento auxiliar. | H13: Financeiro | I13: Voucher Documental | J13: Baixo Impacto | L13: • 31/12/2021 • Recorrente ■ Vorcon Auditoria & Consultoria ■ 24/06/2022
B14: V07 | C14: Acesso a Convenção do Condomínio | D14: Verificamos que o Condomínio não possui site, o ideal seria ter um site e disponibiliar o requimento Regimento nele. | E14: N/A | F14: As melhores práticas de gestão sugerem que as informações do Condomínio estejam de fácil acesso para qualquer condômino. | G14: Sugerimos que o Condomínio contate a sua equipe de TI e verifique a possibilidade de criar um site do Condomínio e disponibilizar a convenção | H14: Operacional | I14: Resumo da Convenção | J14: Baixo Impacto | L14: • 31/12/2021 • Recorrente ■ Vorcon Auditoria & Consultoria ■ 24/06/2022
B15: V08 | C15: Os balancetes sem aprovação dos conselheiros fiscais no termo de aprovação. | D15: Nos meses 01/2021 à 12/2021 não constam as assinaturas dos conselheiros fiscais e do síndico para aprovação dos balancetes. | E15: N/A | F15: A falta das assinaturas dos conselheiros fiscais nos termos de aprovação dos balancetes indica que as contas do condomínio não foram submetidas ao exame, acarretando a redução do nível de confiança dos demonstrativos e podendo prejudicar a leitura dos usuários. | G15: Sugerimos que os conselheiros fiscais realizem o exame dos balancetes e caso ocorra a aprovação dos mesmos, confirmem com as suas assinaturas nos termos de aprovação. Mesmo com as demonstrações financeiras sendo auditadas mensalmente, é necessário a validação do conselho fiscal. | H15: Operacional | I15: Resumo da Convenção | J15: Baixo Impacto | L15: • 31/12/2021 • Novo ■ Vorcon Auditoria & Consultoria ■ 24/06/2022
B16: V09 | C16: Impacto com os inadimplentes | D16: Verificamos que a inadimplência na data base de 31/12/2021 foi equivalente a R$ 23.053,25 atualizados com multas, juros e correção. | E16: 23053.25 | F16: O alto índice de inadimplência condominial impacta inicialmente o orçamento do condomínio. Assim, é preciso compensar de alguma forma o déficit orçamentário para que as obrigações condominiais sejam cumpridas. Como alternativas para essas compensações, podem ser ajustados os valores das taxas condominiais, utilizados os seus fundos de reserva ou criadas taxas extras, gerado assim, prejuízos aos condomínios adimplentes e a toda estrutura financeira condominial. Ademais, ocorre as implicações de ordem interpessoal para que ocorra a regularização dos valores, o que em casos mais graves necessita de cobrança judicial, gerando outros gastos com honorários advocatícios e custas judiciais. | G16: Indicamos à administração ações preventivas que tenham como objetivo a redução das despesas condominiais, o fortalecimento do fundo de reserva e a cobrança de maneira assertiva dos inadimplentes. Além disso, devem ser buscadas alternativas analisando a relação de custos e benefícios para solução desse problema, como por exemplo, a utilização dos serviços de uma garantidora de condomínio. | H16: Financeiro | I16: Inadimplentes | J16: Médio Impacto | L16: • 31/12/2021 • Recorrente ■ Vorcon Auditoria & Consultoria ■ 24/06/2022
B17: V10 | C17: Ausência de Inventário dos ativos imobilizados | D17: Não foi possível identificar o controle patrimonial dos ativos imobilizados do condomínio. | E17: N/A | F17: A ausência do controle patrimonial, o condomínio poderá impactar em possíveis perdas ou desvios do ativo imobilizado. | G17: Sugerimos à Administração do condomínio que busque realizar o inventário dos ativos imobilizados anualmente. | H17: Financeiro | I17: Ativo imobilizado | J17: Alto Impacto | L17: • 31/12/2021 • Recorrente ■ Vorcon Auditoria & Consultoria ■ 24/06/2022
B18: V11 | C18: Inexistência de informações para emissão da certidão de FGTS na Caixa econômica Federal. | D18: Ao realizar a consulta do Certificado de Regularidade Do FGTS, obtivemos a seguinte resposta: "As informações disponíveis não são suficientes para a comprovação automática da regularidade do empregador perante o FGTS. Solicitamos acessar o portal Conectividade Social, mediante certificado ICP, para verificar possíveis impedimentos ou comparecer a uma das Agências da CAIXA". Com esclarecimentos adicionais no endereçamento. | E18: N/A | F18: A inexistência dos dados para emissão da certidão junto ao Caixa, poderá resultar no agravamento do acompanhamento das certidões. | G18: Sugerimos que a administração entre no portal Conectividade Social da Caixa e faça o entendimento de quais dados estão faltando para verificar possíveis impedimentos. | H18: Legal | I18: Certidão | J18: Alto Impacto | L18: • 31/12/2021 • Recorrente ■ Vorcon Auditoria & Consultoria ■ 24/06/2022
B19: V12 | C19: Capacidade de arrecadação inferior aos gastos. | D19: As receitas do meses 02, 04, 07, 09, 10 e 12/2021 não estão sendo suficiente para cobrir as despesas, acarretando em um défict no total nesses meses de - R$ 235.528,38 | E19: -235528.38 | F19: Com as despesas elevadas, o condomínio não consegue arcar com 100% das suas obrigações afetando o fluxo de caixa do financeiro, e ao mesmo tempo não consegue atingir um valor médio ou alto para o fundo de reserva para um futuro inesperado. | G19: Recomendamos ao Conselho Fiscal e a Administração condominial que verifique novas ações a realizar para redução das despesas mitigando ou solucionando o problema. | H19: Estratégico | I19: Demonstrativo de Receita e Despesas | J19: Alto Impacto | L19: • 31/12/2021 • Recorrente ■ Vorcon Auditoria & Consultoria ■ 24/06/2022
B20: V13 | C20: Envio de Boleto Fraudado | D20: Identificamos que o Condomínio enviou um possível boleto fraudado para a Condômina Jussara Barros da Unidade 2801 B no Mês 01/2021 na qual realizou o pagamento. O condomínio necessitou realizar a baixa do valor pago da condômina resultando em prejuízo financeiro de R$ 919,14. | E20: 919.14 | F20: A falta de processo da análise do controle interno das contas a pagar sobre a verificação dos envios dos boletos recebidos pelo Advogado, poderá acarretar em envios de boletos errôneos e gerar prejuízos ao condomínio e a toda estrutura financeira condominial. | G20: Recomendamos a Administração do Condomíonio verifique ações de controles internos para verificação dos boletos enviados aos clientes. | H20: Operacional | I20: Demonstrativo de Receita e Despesas | J20: Baixo Impacto | L20: • 31/12/2021 • Novo ■ Vorcon Auditoria & Consultoria ■ 24/06/2022
B21: V14 | C21: Débito automático referente ao bloqueio judicial | D21: Identificamos nos extratos e nas despesas operacionais que houve o débito automático de de R$ 1.045,19 no mês 8/2021 e de R$ 420,069 no mês 09/2021 referente ao bloqueio judicial. | E21: 1465.259 | F21: Os gastos com bloqueios judiciais geram possíveis prejuízos ao condomínio e a toda estrutura financeira condominial. | G21: Sugerimos a Administração do Condomínio que mantenha o monitoramento constante dos processos financeiros e judicial acompanhando os processos em andamento. | H21: Legal | I21: Extratos | J21: Médio Impacto | L21: • 31/12/2021 • Novo ■ Vorcon Auditoria & Consultoria ■ 24/06/2022
B22: V15 | C22: Saldo bloqueado Custódia de Caução. | D22: Identificamos que durante os meses 09, 10, 11 e 12/2021 o condomínio está em opção custodia caução no valor R$ 4.889,37 nas contas, Bradesco e Caixa Econômica devido a cancelamento do acesso ao conta CEF não foi possível atualizar o saldo das contas. | E22: 4889.37 | F22: Devido ao bloqueio do saldo da conta CEF, não foi possível atualizar o saldo das contas nos meses 09, 10, 11 e 12/2021 podendo afetar diretamente o fluxo de caixa e o controle do financeiro do condomínio. | G22: Sugerimos que a administração entre em contato com a Caixa Econômica Federal e verificar os possíveis impedimentos. | H22: Financeiro | I22: Demonstrativo de Receita e Despesas | J22: Baixo Impacto | L22: • 31/12/2021 • Novo ■ Vorcon Auditoria & Consultoria ■ 24/06/2022
B23: V16 | C23: Não há classificação de expectativa de ganho para algumas causas ativas e de perda para as passivas. | D23: Não há classificação de expectativa de ganho para algumas causas ativas e de perda para as passivas. | E23: 22000 | F23: Verificamos os relatórios de contingências de 2021 e não identificamos quais expectativas de ganho ou perda no contrato. • Passivas – montante de R$ 22.000,00 | G23: Recomendamos que o jurídico do condomínio forneça informações relativa a estimativa de perda ou ganhos dos processos ativos. | H23: Legal | I23: Contigência | J23: Alto Impacto | L23: • 31/12/2021 • Novo ■ Vorcon Auditoria & Consultoria ■ 24/06/2022
B24: V17 | C24: Perda de Causa Judicial | D24: Indentificamos que durante o período de 2021 que há perda de causa judicial de R$ 10.477,17 referente ao n° 0101419-55.2017.8.05.0001 de TICIANA CARNEIRO DA ROCHA PRATA MONTEIRO X TRIBECA, e R$ 29.000,00 referente ao n° 0164073-44.2018.8.05.0001 de RAFAEL CALDAS LOPES X TRIBECA, totalizando em uma perda de R$ 39.477,17 | E24: =29000+10477.17 -> 39477.17 | F24: Devido a perda das causas judicais podendo afetar diretamente o fluxo de caixa e o controle do financeiro do condomínio. | G24: Recomendamos ações preventivas nas melhorias no controle interno para que as causas judiciais não sejam abertas contra o condomínio. | H24: Legal | I24: Contigência | J24: Alto Impacto | L24: • 31/12/2021 • Novo ■ Vorcon Auditoria & Consultoria ■ 24/06/2022

Sheet Matriz de Risco
B6: BASE DA MATRIZ
B7: [P01] | C7: Não foi estabelecida a confiança nos controles que estão implementados no Condomínio Le Parc Residential Resort. | D7: Alto Impacto | E7: Operação Administrativa do Condomínio
B8: [P02] | C8: Ausência de manual de normas e procedimentos | D8: Alto Impacto | E8: Manual de normas e procedimentos
B9: [P03] | C9: Diferenças entre: Favorecido do documento X Beneficiário do pagamento | D9: Alto Impacto | E9: Inspeção Documental - Gastos
B10: [P04] | C10: Pagamentos realizados sem os respectivos comprovantes de pagamento anexados | D10: Alto Impacto | E10: Inspeção Documental - Gastos
B11: [P05] | C11: Diferenças entre: Valor do comprovante de pagamento X Valor da documentação suporte. | D11: Alto Impacto | E11: Inspeção Documental - Gastos
B12: [P06] | C12: Inexistência de rotina de inventário físico do ativo imobilizado. | D12: Alto Impacto | E12: Imobilizado
B13: [P07] | C13: Definição de vida útil do ativo imobilizado | D13: Médio Impacto | E13: Imobilizado
B14: [P08] | C14: Páginas não numeradas ou numeradas de forma incorreta. | D14: Baixo Impacto | E14: Controle Interno
B15: [P09] | C15: Registro da Convenção do Condomínio Le Parc Residential Resort em cartório. | D15: Alto Impacto | E15: Convenção
B16: [P10] | C16: Registro do Regimento do Condomínio Le Parc Residential Resort em cartório. | D16: Alto Impacto | E16: Regimento do Condomínio
B17: [P11] | C17: Não há classificação de expectativa de ganho para algumas causas ativas e de perda para as passivas. | D17: Baixo Impacto | E17: Contingências
B18: [P12] | C18: Inexistência de padronização dos relatórios mensais de contingência | D18: Médio Impacto | E18: Contingências
B19: [P13] | C19: Relatório de encaminhamento aos órgãos de proteção ao crédito. | D19: Médio Impacto | E19: Contingências

Sheet RESUMO DE PONTOS Original
F3: Avaliação da soma das NFs Identificadas | I3: Leilane ajustar | J3: JULGAMENTO PROFISSIONAL | L3: Utilizar essa estrutura no Status
B4: 1 | C4: 2 | D4: 3 | E4: 4 | F4: 5 | G4: 6 | H4: 7 | I4: 8 | J4: 9 | K4: Status | L4: Estrutura
B5: Ponto | C5: Descrição Resumida | D5: Descrição do Ponto | E5: Riscos e Implicações | F5: Impacto Financeiro | G5: Recomendações | H5: Tipo | I5: Tipo de Teste
B6: [P1] | C6: Pagamento sem nota fiscal | D6: Verificamos que ocorreram gastos sem a respectiva emissão de nota fiscal pelos fornecedores e prestadores de serviços. | E6: Pagamento sem os respectivos Fornecedores/ Prestadores de serviços não é permitido pela legislação brasileira assim como Convenção e Regimento Interno do Condomínio. | F6: N/A | G6: Sugerimos que seja solicitado aos respectivos Fornecedores/ Prestadores de serviços ou fornecedores a nota fiscal pelo fornecimento de material ou de prestação de serviços. | H6: Estratégico | I6: Operação Administrativa do Condomínio | J6: MÉDIO IMPACTO | K6: • 31/12/2020 • Recorrente ■ Vorcon Auditoria & Consultoria ■ 22 de abril de 2021 | L6: • [Data base do relatório] • Ponto Novo ou Recorrente??? ■ Empresa que Identificou o Ponto ■ 22 de abril de 2021 [Data do relatório]
B7: [P2] | C7: Diferenças entre: Favorecido do documento X Beneficiário do pagamento | D7: O fornecedor apresentado no comprovante de pagamento não é o mesmo da Nota Fiscal. | E7: Pagamento sem as respectivas notas fiscais não é permitido pela legislação brasileira assim como Convenção e Regimento Interno do Condomínio. | F7: N/A | G7: Sugerimos que seja solicitado aos respectivos prestadores de serviço ou fornecedores a nota fiscal pelo fornecimento de material ou de prestação de serviços. | H7: Operacional | I7: Manual de normas e procedimentos | J7: BAIXO IMPACTO | K7: • 31/12/2020 ■ Vorcon Auditoria & Consultoria ■ 22 de abril de 2021
B8: [P3] | C8: Pagamentos realizados sem os respectivos comprovantes de pagamento anexados | D8: Verificamos que alguns pagamentos foram realizados sem que fossem anexados os respectivos comprovantes de pagamentos ou documentos equivalentes dando a respectiva quitação. | E8: Pagamento duplicado dos valores, ou caso haja a solicitação do comprovante de pagamento o Condomínio não os possua. | F8: N/A | G8: Sugerimos que sejam criados processos para que os comprovantes de pagamentos estejam anexados ao processo de pagamentos. | H8: Operacional | I8: Inspeção Documental - Gastos | J8: ALTO IMPACTO | K8: • 31/12/2020 ■ Vorcon Auditoria & Consultoria ■ 22 de abril de 2021
B9: [P4] | C9: Pagamento de impostos sem identificação do prestador de serviços | D9: Não identificamos documentação suporte que indique a origem dos impostos e os respectivos prestadores de serviço. | E9: Possíveis pagamentos duplicado dos valores, ou caso haja a solicitação do comprovante de pagamento o Condomínio não os possua | F9: N/A | G9: Sugerimos que sejam criados processos para que todos os documentos estejam anexados ao processo de prestação de contas no demonstrativo financeiros. | H9: Operacional | I9: Inspeção Documental - Receitas | J9: MÉDIO IMPACTO | K9: • 31/12/2020 ■ Vorcon Auditoria & Consultoria ■ 22 de abril de 2021
B10: [P5] | C10: Conjunto de documentos sem apresentação de mapa de orçamentos. | D10: Verificamos que muitas das compras realizadas não estavam anexados os mapas de orçamento. | E10: Agindo dessa forma, não estão em conformidade com as normas do estatuto vigente do condomínio. | F10: N/A | G10: Seja realizada a conferência na pré-compra, se estão observando as normas do mapa do orçamento | H10: Estratégico | I10: Imobilizado | J10: BAIXO IMPACTO | K10: • 31/12/2020 ■ Vorcon Auditoria & Consultoria ■ 22 de abril de 2021
B11: [P6] | C11: Inexistência de tempestividade na prestação de contas do fundo fixo | D11: Verificamos que o fundo fixo do Condomínio, por diversas vezes, possui valores retirados onde existe a prestação de contas nos meses não referentes. | E11: Não sendo apresentadas tempestivamentes as apresentações das contas do fundo fixo, afetará diretamente o fluxo de caixa e o controle do fundo fixo do condomínio. | F11: N/A | G11: Seja elaborada uma periodicidade fixa para apresentação das contas do fundo fixo, e que seja realizado as prestações dos períodos correspondentes as despesas. | H11: Operacional | I11: Controle Interno | J11: ALTO IMPACTO | K11: • 31/12/2020 ■ Vorcon Auditoria & Consultoria ■ 22 de abril de 2021
B12: [P7] | C12: Inconsistência na apresentação da atividade da empresa | D12: O serviço/produto adquirido não condiz com a atividade econômica apresentada no CNPJ da empresa. | E12: Afeta diretamente nos cálculos de retenções de impostos do condomínio, se a empresa prestadora de serviço siga a legislação que não à apresentada. | F12: N/A | G12: Criação de um passo a passo na empresa contratada na intenção de verificar a sua atividade perante a forma de tributação. | H12: Estratégico | I12: Regimento | J12: MÉDIO IMPACTO | K12: • 31/12/2020 ■ Vorcon Auditoria & Consultoria ■ 22 de abril de 2021
B13: [P8] | C13: Negligência na gestão dos Documentos que compõe os Demonstrativos | D13: Verificamos que alguns comprovantes não estão sendo arquivados com os cuidados necessários, com isso alguns estão ilegíveis. | E13: Dificuldade na visualização dos gastos e impossibilidade e dúvidas quanto a possíveis consultas no futuro em função do estado dos documentos. | F13: N/A | G13: Sugerimos que sejam criados processos para que os comprovantes sejam de responsabilidade de quem incorre no gasto sendo de responsabilidade do financeiro tirar cópia dos comprovantes ou digitaliza-los assim que os receber. | H13: Operacional | I13: 02.1.2 STC - Voucher documental | J13: BAIXO IMPACTO | K13: • 31/12/2020 • Recorrente ■ Vorcon Auditoria & Consultoria ■ 22 de abril de 2021
B14: [P9] | C14: Conjunto de documentos sem composição clara do valor pago | D14: Verificamos que existe apresentação de despesa sem os respectivos comprovantes de pagamentos. | E14: Pagamento sem os respectivos comprovante de pagamento não é permitido pela Convenção e Regimento Interno do Condomínio. | F14: N/A | G14: Criação de um passo a passo para verificação nos comprovantes de pagamentos das despesas do condomínios. | H14: Operacional | I14: Inspeção Documental - Gastos | J14: ALTO IMPACTO | K14: • 31/12/2020 ■ Vorcon Auditoria & Consultoria ■ 22 de abril de 2021
B15: [P10] | C15: Páginas não numeradas ou numeradas de forma incorreta | D15: Verificamos que algumas páginas do Demonstrativo Financeiro não estão sendo numeradas ou não seguem uma ordem sequencial. | E15: Falhas na padronização implica em perda de eficiência na conferência das prestações de contas. | F15: N/A | G15: Sugerimos que seja criada rotina de revisão da padronização dos Demonstrativos Financeiros mensais, pois isso mitigará possivéis falhas. | H15: Operacional | I15: 02.1.2 STC - Voucher documental | J15: MÉDIO IMPACTO | K15: • 31/12/2020 • Recorrente ■ Vorcon Auditoria & Consultoria ■ 22 de abril de 2021
B16: [P11] | C16: Pagamento de tarifa bancária. | D16: Verificamos que ocorreram pagamento de fornecedores e prestadores de serviços por meio de transferência bancária. | E16: Pagamento de encargos financeiros que deveriam ser de responsabilidade dos Fornecedores/Prestadores de serviços. | F16: N/A | G16: Sugerimos que seja solicitado boleto para pagamento de todos os Fornecedores/Prestadores de serviços e em caso de negativa o valor dos encargos financeiros deve ser subtraído do pagamento. | H16: Financeiro | I16: Inspeção Documental - Gastos | J16: BAIXO IMPACTO | K16: • 31/12/2020 • Recorrente ■ Vorcon Auditoria & Consultoria ■ 22 de abril de 2021
B17: [P12] | C17: Conjunto de documentos anexados fora do mês correspondente. | D17: Desorganização da documentação suporte dificultam a análise de todas as partes envolvidas. | E17: Não sendo apresentadas tempestivamentes as apresentações das contas, afetará diretamente o fluxo de caixa e o controle do financeiro do condomínio. | F17: N/A | G17: Seja elaborada uma periodicidade fixa para apresentação das despesas, e que seja realizado as prestações dos períodos correspondentes as despesas. | H17: Operacional | I17: Inspeção Documental - Gastos | J17: ALTO IMPACTO | K17: • 31/12/2020 ■ Vorcon Auditoria & Consultoria ■ 22 de abril de 2021
B18: [P13] | C18: Conjunto de documentos anexados no balancete sem o mesmo constarem nos demonstrativos financeiros mensais de gastos. | D18: Ausência de transparência na prestação de contas e aumento do risco de pagamentos indevidos. | E18: A apresentação no balancetes sem os respectivos comprovantes do demonstrativos financeiros não é permitido pela legislação brasileira e pela Convenção e Regimento Interno do Condomínio. | F18: N/A | G18: Seja elaborada uma periodicidade fixa para apresentação dos respectivos comprovantes nos balancetes e que seja realizado as prestações dos períodos correspondentes as despesas. | H18: Operacional | I18: Inspeção Documental - Gastos | J18: MÉDIO IMPACTO | K18: • 31/12/2020 ■ Vorcon Auditoria & Consultoria ■ 22 de abril de 2021
... B30: [P28] | C30: Fornecedores citados na resposta de circulação indevidamente | D30: Em resposta na carta de circularização foram citados os seguintes fornecedores: Grupo Contínua - 07.536.483/0001-92, Ecowash - 11.877.873/0001-01, Elemidia - 03.616.039/0001-26, Izar Park - 18.021.222/0001-56, Posto Mataripe - 13.578.265/0001-13, LA Construções - 20.726.309/0001-70, Softdados - 17.869.823/0001-50, Grupo Solução - 23.105.423/0001-71 e Coopcicla - 01.397.759/0001-12, contudo não houveram pagamentos no período em que a auditoria está sendo realizada, informação confirmada posteriormente pela Administração. | E30: Dificuldade quanto ao rastreamentos dos contratos e incerteza quanto a informação apresentada. | F30: N/A | G30: Recomendamos que sejam tomadas as medidas necessárias para que haja um padrão sobre apresentação das informações do contrato e sejam apresentadas conforme solicitado. | H30: Operacional | I30: 02.2.9 STC - Validação da carta de representação de contratos | J30: BAIXO IMPACTO | K30: • 31/12/2020 • Recorrente ■ Vorcon Auditoria & Consultoria ■ 22 de abril de 2021
B31: [P29] | C31: Não há controle de recolhimento do FGTS das empresas terceirizadas | D31: Não nos foi encaminhado um controle de recolhimento a respeito do recolhimento do FGTS dos funcionários que trabalham de forma terceirizada no condomínio. Esse controle é necessário tendo em vista que o condomínio é subsidiariamente responsável pelos recolhimentos tributários e trabalhistas assim como legisla a Súmula 331, IV, do TST | E31: Recolhimento do FGTS sobre os funcinonarios contratados de forma terceirizados. | F31: 1086628.7 | G31: Recomendamos ter um controle de recolhimentos dos funcionários contratados de forma terceirizado. | H31: Operacional | I31: 02.3.3 STC - Recalculo individual de Colaboradores (Validar quantidade com o gestor do projeto) | J31: ALTO IMPACTO | K31: • 31/12/2020 • Novo ■ Vorcon Auditoria & Consultoria ■ 22 de abril de 2021
B32: [P30] | C32: Inexistência de atualização dos Relatórios Jurídicos | D32: Solicitamos a Administração os relatórios jurídicos para o período do trabalho realizado, contudo após a relaização dos testes verificamos que os relatórios disponibilizados apesar de serem de meses diferentes não possuem diferença. Dessa forma há dúvidas se os mesmos estão sendo atualizados ou não. | E32: Possível risco de informações desatualizadas que podem gerar saídas de caixa não programadas para o Condomínio. | F32: N/A | G32: Sugerimso que os relatórios sejam atualizados mensalmente com a expectativa real do valores e ações. Conforme atualização dos processos. | H32: Financeiro | I32: Contingências | J32: BAIXO IMPACTO | K32: • 31/12/2020 • Novo ■ Vorcon Auditoria & Consultoria ■ 22 de abril de 2021
B33: [P31] | C33: Inexistência de expectativa de Ganho e Perda para os Relatórios Jurídicos. | D33: Os relatórios jurídicos apresentados pela Administração não possuem a expectativa de perda ou ganho dos mesmos, conforme prática usual dos assesores jurídicos. | E33: A inêxistência da classificação quanto a possiveis perdas faz com que a Adiministração não possa planejar possiveis saídas de caixas futuras, e além disso tal prática não contempla as melhores práticas de mercado. | F33: N/A | G33: Sugiro que a Administração solicite aos seus Assessores jurídicos que mensalmente os relatórios sejam classificados tanto para perda ou para ganho como: Remota: Prognóstico de perda deve ser menos do que 25% Possível: Prognóstico de perda desde que o risco não seja remoto Provável: Prognóstico de perda deve ser mais do que 50% | H33: Financeiro | I33: 02.3.6 STC - Validação da Carta de Representação de Assessores Jurídicos | J33: BAIXO IMPACTO | K33: • 31/12/2020 • Novo ■ Vorcon Auditoria & Consultoria ■ 22 de abril de 2021
B34: [P32] | C34: Inexistência de politica de acompanhamento das principais certidões. | D34: A Administração não possui como rotina o acompanhamento das principais certidões: Municipal; Estaduas; Federal e; Serviço de proteção de Crédito. | E34: A inexistência do acompanhamento de forma preventiva das certidões pode vir a gerar desembolsados não esperados assim como possíveis bloqueios que podem vir a afetar a rotina do Condomínio. | F34: N/A | G34: Sugerimos que a Administração avalie adicionar em sua rotina, pelo menos trimestral, a emissão dessas certidões como forma de mitigar possíveis problemas. | H34: Legal | I34: 02.3.4 STC - Certidões | J34: MÉDIO IMPACTO | K34: • 31/12/2020 • Novo ■ Vorcon Auditoria & Consultoria ■ 22 de abril de 2021
B35: [P33] | C35: Limitação de escopo | D35: A administração não possui acompanhamento para a rotina de cobrança feita aos condominos inadimplentes | E35: A não entrega de documentos ou evidencias solicitadas impedem que processos possam ser avaliados no decorrer da auditoria | F35: N/A | G35: Se faz necessário que a administração do condominio possua uma rotina ou sistema de cobrança de inadimplentes | H35: Operacional | I35: 02.2.5 STC - Walkthrough de Receita | J35: MÉDIO IMPACTO | K35: • 31/12/2020 • Recorrente ■ Vorcon Auditoria & Consultoria ■ 22 de abril de 2021

Sheet RESUMO DE PONTOS
B3: Condomínio Parque Tropical | E3: Materialidade | F3: 141950 | G3: Total da Receita
B4: RESUMO DE PONTOS | E4: PM | F4: 95800 | G4: 4731498.7
B5: Data base: 01/01/2019 à 31/12/2021 | E5: AMPT | F5: 7100 | M5: ATUALIZAR
G6: Avaliação da soma das NFs Identificadas
B7: COD | C7: 1 | D7: 2 | E7: 3 | F7: 4 | G7: 5 | H7: 6 | I7: 7 | J7: 8 | L7: 9 | M7: Status | N7: Perdas/Impacto
B8: Código | C8: Ponto | D8: Descrição Resumida | E8: Descrição do Ponto | F8: Riscos e Implicações | G8: Impacto Financeiro | H8: Recomendações | I8: Tipo | J8: Tipo de Teste | K8: Tipo de Teste | L8: Julgamento Profissional
B9: V01 | C9: [P1] | D9: =_xlfn.XLOOKUP($B9,'BASE DE PONTOS V+'!$B:$B,'BASE DE PONTOS V+'!$C:$C) -> Pagamento sem nota fiscal | E9: =_xlfn.XLOOKUP($B9,'BASE DE PONTOS V+'!$B:$B,'BASE DE PONTOS V+'!$D:$D) -> Verificamos que ocorreram gastos sem a respectiva emissão de nota fiscal pelos fornecedores e prestadores de serviços. | F9: =_xlfn.XLOOKUP($B9,'BASE DE PONTOS V+'!$B:$B,'BASE DE PONTOS V+'!$F:$F) -> Pagamento sem os respectivos Fornecedores/Prestadores de serviços não é permitido pela legislação brasileira assim como Convenção e Regimento Interno do Condomínio podendo ser multado e/ou sofrer outras penalidades impostas pelo fisco. | G9: =_xlfn.XLOOKUP(B9,'BASE DE PONTOS V+'!B:B,'BASE DE PONTOS V+'!E:E) -> 47819.88 | H9: =_xlfn.XLOOKUP($B9,'BASE DE PONTOS V+'!$B:$B,'BASE DE PONTOS V+'!$G:$G) -> Sugerimos que seja solicitado aos respectivos Fornecedores/ Prestadores de serviços ou fornecedores a nota fiscal pelo fornecimento de material ou de prestação de serviço. | I9: =_xlfn.XLOOKUP($B9,'BASE DE PONTOS V+'!$B:$B,'BASE DE PONTOS V+'!$H:$H) -> Legal | J9: =_xlfn.XLOOKUP($B9,'BASE DE PONTOS V+'!$B:$B,'BASE DE PONTOS V+'!$I:$I) -> Voucher Documental | K9: =_xlfn.XLOOKUP($B9,'BASE DE PONTOS V+'!$B:$B,'BASE DE PONTOS V+'!$M:$M) -> 0 | L9: =_xlfn.XLOOKUP(B9,'BASE DE PONTOS V+'!B:B,'BASE DE PONTOS V+'!J:J) -> Alto Impacto | M9: =_xlfn.XLOOKUP(D9,'BASE DE PONTOS V+'!C:C,'BASE DE PONTOS V+'!L:L) -> • 31/12/2021 • Recorrente ■ Vorcon Auditoria & Consultoria ■ 24/06/2022 | N9: =IF(B9="","",IFERROR(IF(I9="Financeiro",VLOOKUP(G9,'BASE DA MATRIZ DE RISCOS'!$O$58:$Q$62,3,1),"Avaliar por julgameto"),"1")) -> Avaliar por julgameto
B10: V03 | C10: [P2] | D10: =_xlfn.XLOOKUP($B10,'BASE DE PONTOS V+'!$B:$B,'BASE DE PONTOS V+'!$C:$C) -> Pagamentos realizados sem os respectivos comprovantes de pagamento anexados | E10: =_xlfn.XLOOKUP($B10,'BASE DE PONTOS V+'!$B:$B,'BASE DE PONTOS V+'!$D:$D) -> Verificamos que alguns pagamentos foram realizados sem que fossem anexados os respectivos comprovantes de pagamentos ou documentos equivalentes dando a respectiva quitação. | F10: =_xlfn.XLOOKUP($B10,'BASE DE PONTOS V+'!$B:$B,'BASE DE PONTOS V+'!$F:$F) -> Pagamento duplicado dos valores, ou caso haja a solicitação do comprovante de pagamento o Condomínio não os possua | G10: =_xlfn.XLOOKUP(B10,'BASE DE PONTOS V+'!B:B,'BASE DE PONTOS V+'!E:E) -> 23309.37 | H10: =_xlfn.XLOOKUP($B10,'BASE DE PONTOS V+'!$B:$B,'BASE DE PONTOS V+'!$G:$G) -> Sugerimos que sejam criados processos para que os comprovantes de pagamentos estejam anexados ao processo de pagamentos | I10: =_xlfn.XLOOKUP($B10,'BASE DE PONTOS V+'!$B:$B,'BASE DE PONTOS V+'!$H:$H) -> Financeiro | J10: =_xlfn.XLOOKUP($B10,'BASE DE PONTOS V+'!$B:$B,'BASE DE PONTOS V+'!$I:$I) -> Voucher Documental | K10: =_xlfn.XLOOKUP($B10,'BASE DE PONTOS V+'!$B:$B,'BASE DE PONTOS V+'!$M:$M) -> 0 | L10: =_xlfn.XLOOKUP(B10,'BASE DE PONTOS V+'!B:B,'BASE DE PONTOS V+'!J:J) -> Alto Impacto | M10: =_xlfn.XLOOKUP(D10,'BASE DE PONTOS V+'!C:C,'BASE DE PONTOS V+'!L:L) -> • 31/12/2021 • Recorrente ■ Vorcon Auditoria & Consultoria ■ 24/06/2022 | N10: =IF(B10="","",IFERROR(IF(I10="Financeiro",VLOOKUP(G10,'BASE DA MATRIZ DE RISCOS'!$O$58:$Q$62,3,1),"Avaliar por julgameto"),"1")) -> 2
B11: V04 | C11: [P3] | D11: =_xlfn.XLOOKUP($B11,'BASE DE PONTOS V+'!$B:$B,'BASE DE PONTOS V+'!$C:$C) -> Negligência na gestão dos Documentos que compõe os Demonstrativos | E11: =_xlfn.XLOOKUP($B11,'BASE DE PONTOS V+'!$B:$B,'BASE DE PONTOS V+'!$D:$D) -> Verificamos que alguns comprovantes não estão sendo arquivados com os cuidados necessários, com isso alguns estão ilegíveis. | F11: =_xlfn.XLOOKUP($B11,'BASE DE PONTOS V+'!$B:$B,'BASE DE PONTOS V+'!$F:$F) -> Dificuldade na visualização dos gastos e impossibilidade e dúvidas quanto a possíveis consultas no futuro em função do estado dos documentos. | G11: =_xlfn.XLOOKUP(B11,'BASE DE PONTOS V+'!B:B,'BASE DE PONTOS V+'!E:E) -> 1087.39 | H11: =_xlfn.XLOOKUP($B11,'BASE DE PONTOS V+'!$B:$B,'BASE DE PONTOS V+'!$G:$G) -> Sugerimos que sejam criados processos para que os comprovantes sejam de responsabilidade do financeiro tirar cópia ou digitalizá-los assim que os receber. | I11: =_xlfn.XLOOKUP($B11,'BASE DE PONTOS V+'!$B:$B,'BASE DE PONTOS V+'!$H:$H) -> Operacional | J11: =_xlfn.XLOOKUP($B11,'BASE DE PONTOS V+'!$B:$B,'BASE DE PONTOS V+'!$I:$I) -> Voucher Documental | K11: =_xlfn.XLOOKUP($B11,'BASE DE PONTOS V+'!$B:$B,'BASE DE PONTOS V+'!$M:$M) -> 0 | L11: =_xlfn.XLOOKUP(B11,'BASE DE PONTOS V+'!B:B,'BASE DE PONTOS V+'!J:J) -> Baixo Impacto | M11: =_xlfn.XLOOKUP(D11,'BASE DE PONTOS V+'!C:C,'BASE DE PONTOS V+'!L:L) -> • 31/12/2021 • Recorrente ■ Vorcon Auditoria & Consultoria ■ 24/06/2022 | N11: =IF(B11="","",IFERROR(IF(I11="Financeiro",VLOOKUP(G11,'BASE DA MATRIZ DE RISCOS'!$O$58:$Q$62,3,1),"Avaliar por julgameto"),"1")) -> Avaliar por julgameto
B12: V05 | C12: [P4] | D12: =_xlfn.XLOOKUP($B12,'BASE DE PONTOS V+'!$B:$B,'BASE DE PONTOS V+'!$C:$C) -> Pagamento de tarifa bancária. | E12: =_xlfn.XLOOKUP($B12,'BASE DE PONTOS V+'!$B:$B,'BASE DE PONTOS V+'!$D:$D) -> Verificamos que ocorreram pagamento de fornecedores e prestadores de serviços por meio de transferência bancária. | F12: =_xlfn.XLOOKUP($B12,'BASE DE PONTOS V+'!$B:$B,'BASE DE PONTOS V+'!$F:$F) -> Pagamento de encargos financeiros que deveriam ser de responsabilidade dos Fornecedores/Prestadores de serviços | G12: =_xlfn.XLOOKUP(B12,'BASE DE PONTOS V+'!B:B,'BASE DE PONTOS V+'!E:E) -> 88.4 | H12: =_xlfn.XLOOKUP($B12,'BASE DE PONTOS V+'!$B:$B,'BASE DE PONTOS V+'!$G:$G) -> Sugerimos que seja solicitado boleto para pagamento de todos os Fornecedores/Prestadores de serviços e em caso de negativa o valor dos encargos financeiros deve ser subtraído do pagamento. | I12: =_xlfn.XLOOKUP($B12,'BASE DE PONTOS V+'!$B:$B,'BASE DE PONTOS V+'!$H:$H) -> Financeiro | J12: =_xlfn.XLOOKUP($B12,'BASE DE PONTOS V+'!$B:$B,'BASE DE PONTOS V+'!$I:$I) -> Voucher Documental | K12: =_xlfn.XLOOKUP($B12,'BASE DE PONTOS V+'!$B:$B,'BASE DE PONTOS V+'!$M:$M) -> 0 | L12: =_xlfn.XLOOKUP(B12,'BASE DE PONTOS V+'!B:B,'BASE DE PONTOS V+'!J:J) -> Baixo Impacto | M12: =_xlfn.XLOOKUP(D12,'BASE DE PONTOS V+'!C:C,'BASE DE PONTOS V+'!L:L) -> • 31/12/2021 • Recorrente ■ Vorcon Auditoria & Consultoria ■ 24/06/2022 | N12: =IF(B12="","",IFERROR(IF(I12="Financeiro",VLOOKUP(G12,'BASE DA MATRIZ DE RISCOS'!$O$58:$Q$62,3,1),"Avaliar por julgameto"),"1")) -> 1
B13: V06 | C13: [P5] | D13: =_xlfn.XLOOKUP($B13,'BASE DE PONTOS V+'!$B:$B,'BASE DE PONTOS V+'!$C:$C) -> Diferenças entre: Valor do comprovante de pagamento X Valor da documentação suporte. | E13: =_xlfn.XLOOKUP($B13,'BASE DE PONTOS V+'!$B:$B,'BASE DE PONTOS V+'!$D:$D) -> Verificamos que há diferença entre os valores apresentados, não justificada por parcelamento ou multa. | F13: =_xlfn.XLOOKUP($B13,'BASE DE PONTOS V+'!$B:$B,'BASE DE PONTOS V+'!$F:$F) -> Possibilidade de pagamentos realizados com valores incorretos. | G13: =_xlfn.XLOOKUP(B13,'BASE DE PONTOS V+'!B:B,'BASE DE PONTOS V+'!E:E) -> 333.3 | H13: =_xlfn.XLOOKUP($B13,'BASE DE PONTOS V+'!$B:$B,'BASE DE PONTOS V+'!$G:$G) -> Sugerimos que os pagamentos sejam realizados com os valores que constam no documento auxiliar. | I13: =_xlfn.XLOOKUP($B13,'BASE DE PONTOS V+'!$B:$B,'BASE DE PONTOS V+'!$H:$H) -> Financeiro | J13: =_xlfn.XLOOKUP($B13,'BASE DE PONTOS V+'!$B:$B,'BASE DE PONTOS V+'!$I:$I) -> Voucher Documental | K13: =_xlfn.XLOOKUP($B13,'BASE DE PONTOS V+'!$B:$B,'BASE DE PONTOS V+'!$M:$M) -> 0 | L13: =_xlfn.XLOOKUP(B13,'BASE DE PONTOS V+'!B:B,'BASE DE PONTOS V+'!J:J) -> Baixo Impacto | M13: =_xlfn.XLOOKUP(D13,'BASE DE PONTOS V+'!C:C,'BASE DE PONTOS V+'!L:L) -> • 31/12/2021 • Recorrente ■ Vorcon Auditoria & Consultoria ■ 24/06/2022 | N13: =IF(B13="","",IFERROR(IF(I13="Financeiro",VLOOKUP(G13,'BASE DA MATRIZ DE RISCOS'!$O$58:$Q$62,3,1),"Avaliar por julgameto"),"1")) -> 1
B14: V07 | C14: [P6] | D14: =_xlfn.XLOOKUP($B14,'BASE DE PONTOS V+'!$B:$B,'BASE DE PONTOS V+'!$C:$C) -> Acesso a Convenção do Condomínio | E14: =_xlfn.XLOOKUP($B14,'BASE DE PONTOS V+'!$B:$B,'BASE DE PONTOS V+'!$D:$D) -> Verificamos que o Condomínio não possui site, o ideal seria ter um site e disponibiliar o requimento Regimento nele. | F14: =_xlfn.XLOOKUP($B14,'BASE DE PONTOS V+'!$B:$B,'BASE DE PONTOS V+'!$F:$F) -> As melhores práticas de gestão sugerem que as informações do Condomínio estejam de fácil acesso para qualquer condômino. | G14: =_xlfn.XLOOKUP(B14,'BASE DE PONTOS V+'!B:B,'BASE DE PONTOS V+'!E:E) -> N/A | H14: =_xlfn.XLOOKUP($B14,'BASE DE PONTOS V+'!$B:$B,'BASE DE PONTOS V+'!$G:$G) -> Sugerimos que o Condomínio contate a sua equipe de TI e verifique a possibilidade de criar um site do Condomínio e disponibilizar a convenção | I14: =_xlfn.XLOOKUP($B14,'BASE DE PONTOS V+'!$B:$B,'BASE DE PONTOS V+'!$H:$H) -> Operacional | J14: =_xlfn.XLOOKUP($B14,'BASE DE PONTOS V+'!$B:$B,'BASE DE PONTOS V+'!$I:$I) -> Resumo da Convenção | K14: =_xlfn.XLOOKUP($B14,'BASE DE PONTOS V+'!$B:$B,'BASE DE PONTOS V+'!$M:$M) -> 0 | L14: =_xlfn.XLOOKUP(B14,'BASE DE PONTOS V+'!B:B,'BASE DE PONTOS V+'!J:J) -> Baixo Impacto | M14: =_xlfn.XLOOKUP(D14,'BASE DE PONTOS V+'!C:C,'BASE DE PONTOS V+'!L:L) -> • 31/12/2021 • Recorrente ■ Vorcon Auditoria & Consultoria ■ 24/06/2022 | N14: =IF(B14="","",IFERROR(IF(I14="Financeiro",VLOOKUP(G14,'BASE DA MATRIZ DE RISCOS'!$O$58:$Q$62,3,1),"Avaliar por julgameto"),"1")) -> Avaliar por julgameto
