Workbook
Name _Hlk102822595: 'BASE DE PONTOS V+'!#REF!
Name _Hlk102822605: 'BASE DE PONTOS V+'!#REF!
Name _Hlk44932008: 'Matriz de Risco'!$C$9
Name _Hlk44932008: 'RESUMO DE PONTOS'!#REF!
Name _Hlk44932008: 'RESUMO DE PONTOS Original'!$C$8
Name _Hlk44932282: 'Matriz de Risco'!$C$13
Name _Hlk44933547: 'Matriz de Risco'!$C$17
Name _Hlk44933737: 'Matriz de Risco'!$C$18
Name _Toc54348655: 'BASE DA MATRIZ DE RISCOS'!$C$19
Name _Toc54348656: 'BASE DA MATRIZ DE RISCOS'!$C$20
Name _Toc54348657: 'BASE DA MATRIZ DE RISCOS'!$C$37
Name _Toc54348658: 'BASE DA MATRIZ DE RISCOS'!$C$46
Name _Toc54348659: 'BASE DA MATRIZ DE RISCOS'!$C$75
Name _Toc54348660: 'BASE DA MATRIZ DE RISCOS'!$C$76
Name _Toc54348662: 'BASE DA MATRIZ DE RISCOS'!$C$119
Name _Toc70060767: TESTES!#REF!
Name _Toc70060768: TESTES!#REF!
Name _Toc70060769: TESTES!#REF!
Name _Toc70060770: TESTES!#REF!
Name _Toc70060771: TESTES!#REF!
Name _Toc70060772: TESTES!#REF!
Name _Toc70060773: TESTES!#REF!
Name _Toc70060774: TESTES!#REF!
Name _Toc70060775: TESTES!#REF!
Name _Toc70060776: TESTES!#REF!
Name _Toc70060777: TESTES!#REF!
Name _Toc70060778: TESTES!#REF!
Name _Toc70060779: TESTES!#REF!
Name _Toc70060780: TESTES!#REF!
Name _Toc70060781: TESTES!#REF!
Name _Toc70060782: TESTES!#REF!
Name _Toc70060783: TESTES!#REF!
Name _Toc70060784: TESTES!#REF!
Name _Toc70060785: TESTES!#REF!
Name _Toc70060786: TESTES!#REF!
Name _Toc70060787: TESTES!#REF!
Name _Toc70060788: TESTES!#REF!
Name _Toc70060789: TESTES!#REF!
Name _Toc70060790: TESTES!#REF!
Name _Toc70060791: TESTES!#REF!
Name _Toc70060792: TESTES!#REF!
Name _Toc70060793: TESTES!#REF!
Name _Toc70060794: TESTES!#REF!
Name _Toc70060795: TESTES!#REF!
Name _Toc70060796: TESTES!#REF!
Name _Toc70060797: TESTES!#REF!
Name _Toc70060798: TESTES!#REF!
Name _Toc70060799: TESTES!#REF!
Name _Toc70060800: TESTES!#REF!
Name _Toc70060801: TESTES!#REF!
Name _Toc70060802: TESTES!#REF!
Name _Toc70060803: TESTES!#REF!
Name _Toc70060804: TESTES!#REF!
Name _Toc70060805: TESTES!#REF!
Name _Toc70060806: TESTES!#REF!
Name _Toc70060807: TESTES!#REF!
Name _Toc70060808: TESTES!#REF!
Name _Toc70060809: TESTES!#REF!
Name _Toc70060810: TESTES!#REF!
Name _Toc70060811: TESTES!#REF!

Sheet TESTES
B2: Condomínio Mar de Itapuã
B3: Testes e Procedimentos da Auditoira Condominial
B4: Data base: 01/01/2021 à 31/12/2021
B6: Etapas | C6: Análise do Contrato - Auditoria conforme a NBC TA 800 | D6: Responsável | E6: Código Vorcon | F6: Cliente | G6: Testes e Procedimentos de Auditoria realizados | H6: Código do Teste | I6: Status testes | J6: Responsável | K6: Pedido de análise | L6: Descrição no Pedido de Análise | M6: Status pedido de análise | N6: Observações | P6: Simbolo | Q6: Tipo | R6: Conclusão
B7: Planejamento | E7: 01.1.1 | F7: CRP | G7: Confirmação de Independência | H7: 01.1.1 - CRP - Confirmação de Independência | M7: x | P7: a | Q7: OK | R7: =COUNTIFS(I7:I54,"a")/COUNTA(H7:H54) -> 0
B8: Planejamento | E8: 01.1.2 | F8: CRP | G8: Pedido de Análise | H8: 01.1.2 - CRP - Pedido de Análise | M8: x | P8: x | Q8: Não Aplicável | R8: =COUNTIFS(I7:I54,"x")/COUNTA(H7:H54) -> 0
B9: Planejamento | E9: 01.1.3 | F9: CRP | G9: Entrevista para entendimento dos controles internos do condomínio (Inquiries) | H9: 01.1.3 - CRP - Entrevista para entendimento dos controles internos do condomínio | M9: x | P9: r | Q9: Pendente | R9: =COUNTIFS(I7:I54,"")/COUNTA(H7:H54) -> 1
B10: Planejamento | E10: 01.1.4 | F10: CRP | G10: Cálculo da Materialidade | H10: 01.1.4 - CRP - Cálculo da Materialidade | M10: a | P10: q | Q10: Em Andamento | R10: =COUNTIFS(I9:I56,"q")/COUNTA(H9:H56) -> 0
B11: Planejamento | E11: 01.1.5 | F11: CRP | G11: Follow Up CCI | H11: 01.1.5 - CRP - Follow Up CCI | M11: a
B12: Preparação | E12: 01.1.6 | F12: CRP | G12: Voucher documental | H12: 01.1.6 - CRP - Voucher documental | M12: a
B13: Preparação | E13: 01.1.7 | F13: CRP | G13: Constituição e operação do Condomínio | H13: 01.1.7 - CRP - Constituição e operação do Condomínio | M13: a
B14: Preparação | E14: 01.1.8 | F14: CRP | G14: Resumo Regimento | H14: 01.1.8 - CRP - Resumo Regimento | M14: a
B15: Preparação | E15: 01.1.9 | F15: CRP | G15: Resumo Convenção | H15: 01.1.9 - CRP - Resumo Convenção | M15: a
B16: Preparação | E16: 01.1.10 | F16: CRP | G16: Resumo do Manual de Obrigações Trabalhistas | H16: 01.1.10 - CRP - Resumo do Manual de Obrigações Trabalhistas | M16: x
B17: Preparação | E17: 01.1.11 | F17: CRP | G17: Resumo do Manual Operacional de Receitas | H17: 01.1.11 - CRP - Resumo do Manual Operacional de Receitas | M17: x
B18: Preparação | E18: 01.1.12 | F18: CRP | G18: Resumo do Manual de Contratação | H18: 01.1.12 - CRP - Resumo do Manual de Contratação | M18: x
B19: Preparação | E19: 01.1.13 | F19: CRP | G19: Carta de Representação de Atas | H19: 01.1.13 - CRP - Carta de Representação de Atas | M19: a
B20: Preparação | E20: 01.1.14 | F20: CRP | G20: Resumo Atas | H20: 01.1.14 - CRP - Resumo Atas | M20: a
B21: Preparação | E21: 01.1.15 | F21: CRP | G21: Teste de voucher (inspeção das guias e confronto dos saldos demonstrativos) | H21: 01.1.15 - CRP - Teste de voucher (inspeção das guias e confronto dos saldos demonstrativos) | M21: a
B22: Preparação | E22: 01.1.16 | F22: CRP | G22: Consolidação dos saldos dos demonstrativos financeiro + Voucher Documental | H22: 01.1.16 - CRP - Consolidação dos saldos dos demonstrativos financeiro + Voucher Documental | M22: a
... B50: Revisão | E50: 01.1.43 | F50: CRP | G50: Consolidação de pontos (baseado no novo modelo com matriz de risco.) | H50: 01.1.43 - CRP - Consolidação de pontos (baseado no novo modelo com matriz de risco.) | M50: x
B51: Revisão | E51: 01.1.44 | F51: CRP | G51: Carta de Representação da Administração | H51: 01.1.44 - CRP - Carta de Representação da Administração
B52: Revisão | E52: 01.1.45 | F52: CRP | G52: Minuta da Auditoria NBC TA 800 | H52: 01.1.45 - CRP - Minuta da Auditoria NBC TA 800
B53: Revisão | E53: 01.1.46 | F53: CRP | G53: Minuta da Apresentação da Auditoria NBC TA 800 | H53: 01.1.46 - CRP - Minuta da Apresentação da Auditoria NBC TA 800
B54: Revisão | E54: 01.1.47 | F54: CRP | G54: Relatório Final da Auditoria NBC TA 800 | H54: 01.1.47 - CRP - Relatório Final da Auditoria NBC TA 800

Sheet OPNIÃO
B1: Condomínios
B2: APROVA | C2: RELATÓRIO COM OPINIÃO SEM RESSALVA | D2: O relatório sem ressalva é emitido quando o auditor está convencido sobre todos os aspectos relevantes dos assuntos tratados no item 4 deste Pronunciamento. O relatório do auditor independente deve expressar essa convicção de forma clara e objetiva. | E2: O relatório sem ressalva implica afirmação de que, em tendo havido alterações em princípios contábeis ou no método de sua aplicação, o fato e os efeitos dele decorrentes foram adequadamente determinados e revelados nas demonstrações contábeis e/ou nas notas explicativas. | F2: O auditor não deve emitir um relatório sem ressalva quando existirem quaisquer das circunstâncias seguintes, que, na sua opinião, tenham efeitos relevantes para as demonstrações contábeis.
B3: APROVA COM RESSALVA | C3: RELATÓRIO COM OPINIÃO COM RESSALVA | D3: O relatório com ressalva é emitido quando o auditor conclui que o efeito de qualquer discordância ou restrição na extensão de um trabalho não é de tal magnitude que requeira relatório adverso ou abstenção de opinião. | E3: O relatório com ressalva deve obedecer ao modelo do relatório sem ressalva, com a utilização das expressões "exceto por", "exceto quanto" ou "com exceção de", referindo-se aos efeitos do assunto objeto da ressalva. Não é aceitável nenhuma outra expressão na redação desse tipo de relatório.
B4: Não APROVA | C4: RELATÓRIO COM OPINIÃO ADVERSO | D4: O auditor deve emitir relatório adverso quando verificar que as demonstrações contábeis estão incorretas ou incompletas, em tal magnitude que impossibilite a emissão do relatório com ressalvas. | E4: Assim, relatório adverso é o que exprime a opinião de que as demonstrações contábeis não representam adequadamente a posição patrimonial e financeira, nem o resultado das operações, e/ou as mutações do patrimônio líquido, e/ou as origens e aplicações de recursos de acordo com os Princípios Fundamentais de Contabilidade. | F4: O auditor deve, portanto, emitir relatório adverso quando verificar efeitos que, em sua opinião, comprometam em tal magnitude das demonstrações contábeis examinadas a ponto de não ser suficiente a simples ressalva no relatório. Nessas circunstâncias, uma ressalva não é considerada apropriada, uma vez que o auditor possui informações suficientes para declarar que as demonstrações contábeis não estão adequadamente apresentadas.
B5: Não APROVA | C5: RELATÓRIO COM ABSTENÇÃO DE OPINIÃO | D5: O relatório com abstenção de opinião é emitido quando houver uma limitação significativa na extensão de seus exames que impossibilite o auditor expressar opinião sobre as demonstrações contábeis por não ter obtido comprovação suficiente para fundamentá-la. Abstenção de opinião por limitação da extensão | E5: Nos casos de limitações significativas, o auditor deve, no parágrafo da extensão, indicar claramente os procedimentos omitidos e suas circunstâncias ou fazer uma referência a um parágrafo intermediário específico do relatório que descreva tal limitação. Em quaisquer desses casos, em parágrafo final do relatório, o auditor deve mencionar claramente que o exame não foi suficiente para permitir emissão de opinião sobre as demonstrações contábeis tomadas em conjunto. A abstenção de opinião não elimina a responsabilidade do auditor em mencionar, no relatório, qualquer desvio relevante que possa influenciar a decisão do usuário dessas informações.
C7: Análise: Quando houver distorção relevante ou não identificação de evidências de que as demonstrações não apresentam distorções relevantes, o auditor deverá modificar sua opinião, entre: opinião com ressalva, adversa ou com abstenção de opinião.
C9: Nessas ocasiões, deve-se atentar para as seguintes palavras-chave:
C11: RELEVANTE + NÃO GENERALIZADA (com ou sem evidências): Opinião com ressalva;
C12: RELEVANTE + GENERALIZADA (com evidência): Opinião Adversa;
C13: RELEVANTE + GENERALIZADA (sem evidência): Abstenção de Opinião.
C15: Tipos de Opinião do Auditor
C17: 1. Opinião com ressalva
C19: O auditor deve expressar uma “Opinião com ressalva” quando:
C21: ele, tendo obtido evidência de auditoria apropriada e suficiente, conclui que as distorções, individualmente ou em conjunto, são relevantes, mas Não Generalizadas nas demonstrações contábeis; ou
C22: não é possível para ele obter evidência apropriada e suficiente de auditoria para fundamentar sua opinião, mas ele conclui que os possíveis efeitos de distorções não detectadas sobre as demonstrações contábeis, se houver, poderiam ser relevantes, MAS NÃO GENERALIZADOS.
C24: 2. Opinião adversa
C26: O auditor deve expressar uma “Opinião adversa” quando, tendo obtido evidência de auditoria apropriada e suficiente, conclui que as distorções, individualmente ou em conjunto, são RELEVANTES E GENERALIZADAS para as demonstrações contábeis.
... C30: O auditor deve se abster de expressar uma opinião quando não consegue obter evidência de auditoria apropriada e suficiente para fundamentar sua opinião e ele concluir que os possíveis efeitos de distorções não detectadas sobre as demonstrações contábeis, se houver, poderiam ser relevantes e generalizados.
D32: Natureza do assunto que gerou a modificação | E32: Julgamento do auditor sobre a disseminação de forma generalizada dos efeitos ou possíveis efeitos sobre as DFs
E33: Não Generalizado | F33: Generalizado
D34: DFs apresentam Distorsões Relevantes | E34: Opinião com Ressalva | F34: Opinião Adversa
D35: Impossibilidade de se Obter Evidência de Auditoria Apropriada e Suficiente | E35: Opinião com Ressalva | F35: Abstenção de Opinião

Sheet VELOCIMETRO
E1: =SUM(E2:E4) -> 0.5
D2: Não Aprova | E2: =50%-E3-E4 -> 0.125 | F2: =E2/$E$1 -> 0.25
D3: Aprova c/Ressalva | E3: 0.125 | F3: =E3/$E$1 -> 0.25
D4: Aprova | E4: 0.25 | F4: =E4/$E$1 -> 0.5
E5: 0.5
E6: Aprova | G6: Aprova c/ Ressalva | I6: Não Aprova | K6: Não Aprova
D7: Total de Pontos de baixo Impacto | E7: 0 | F7: =K23 -> 0.15384615 | G7: 2 | H7: =G7/$G$10 -> 0.14285714 | I7: 15 | J7: =I7/$I$10 -> 0.6 | K7: 15 | L7: =K7/$K$10 -> 0.42857143
D8: Ponteiro | E8: 5 | F8: 0.01 | G8: 5 | H8: =G8/$G$10 -> 0.35714286 | I8: 5 | J8: =I8/$I$10 -> 0.2 | K8: 10 | L8: =K8/$K$10 -> 0.28571429
D9: Total de Pontos de alto Impacto | E9: 15 | F9: =K21 -> 0.61538462 | G9: 7 | H9: =G9/$G$10 -> 0.5 | I9: 5 | J9: =I9/$I$10 -> 0.2 | K9: 10 | L9: =K9/$K$10 -> 0.28571429
E10: =SUM(E7:E9) -> 20 | F10: =SUM(F7:F9) -> 0.77923077 | G10: =SUM(G7:G9) -> 14 | H10: =SUM(H7:H9) -> 1 | I10: =SUM(I7:I9) -> 25 | J10: =SUM(J7:J9) -> 1 | K10: =SUM(K7:K9) -> 35 | L10: =SUM(L7:L9) -> 1
D12: 0% - 50% | E12: Se, pelo menos 75% dos pontos forem de baixo impacto e não houver nenhum ponto de Alto impacto crítico o bastante para reprovar as contas
D13: 51% - 75% | E13: Se a maioria dos pontos forem de Média e Baixo Impacto e houverem pouco s pontos de alto impacto ( pelo menos 75% forem de pontos de médio e baixo impacto e nos pontos de alto impacto não haver nenhum ponto crítico o bastante para reprovar as contas.
D14: 75% - 90% | E14: Se a maioria dos pontos forem de alto Impacto e houverem poucos pontos de baixo e médio impacto ( pelo menos 75% forem de pontos de alto impacto e nos pontos de alto impacto não haver nenhum ponto crítico o bastante para reprovar as contas.
D15: Crítico ( 100% ) | E15: Se houver algum ponto crítico o bastante que a auditoria julgue que seja impactante o suficiente para não permitir a aprovação das contas ou haja limitação de escopo que não permita que a auditoria seja realizada.
E20: Ponto | F20: Tipo | G20: Quantidade
E21: P01 | F21: ALTO | G21: 1 | I21: Alto | J21: =SUMIF($F$21:$F$46,$I21,$G$21:$G$46) -> 8 | K21: =J21/$J$24 -> 0.61538462
E22: P02 | F22: ALTO | G22: 1 | I22: Médio | J22: =SUMIF($F$21:$F$46,$I22,$G$21:$G$46) -> 3 | K22: =J22/$J$24 -> 0.23076923
E23: P03 | F23: ALTO | G23: 1 | I23: Baixo | J23: =SUMIF($F$21:$F$46,$I23,$G$21:$G$46) -> 2 | K23: =J23/$J$24 -> 0.15384615
E24: P04 | F24: ALTO | G24: 1 | J24: =SUM(J21:J23) -> 13 | K24: =SUM(K21:K23) -> 1
E25: P05 | F25: ALTO | G25: 1
E26: P06 | F26: ALTO | G26: 1
E27: P07 | F27: MÉDIO | G27: 1
E28: P08 | F28: BAIXO | G28: 1
E29: P09 | F29: ALTO | G29: 1
E30: P10 | F30: ALTO | G30: 1
E31: P11 | F31: BAIXO | G31: 1
E32: P12 | F32: MÉDIO | G32: 1
E33: P13 | F33: MÉDIO | G33: 1
E34: P14 | G34: 1
E35: P15 | G35: 1
E36: P16
E37: P17
E38: P18
E39: P19
E40: P20
E41: P21
E42: P22
E43: P23
E44: P24
E45: P25
...

Sheet RESUMO DE PONTOS
B3: ='BASE DE PONTOS V+'!B2 -> Condomínio Reserva das Plantas | E3: Materialidade | F3: 149800
B4: RESUMO DE PONTOS | E4: PM | F4: 93650 | G4: 4994518.8
B5: Data base: | E5: AMPT | F5: 7490 | M5: ATUALIZAR
G6: Avaliação da soma das NFs Identificadas
B7: COD | C7: 1 | D7: 2 | E7: 3 | F7: 4 | G7: 5 | H7: 6 | I7: 7 | J7: 8 | L7: 9 | M7: Status | N7: Perdas/Impacto
B8: Código | C8: Ponto | D8: Descrição Resumida | E8: Descrição do Ponto | F8: Riscos e Implicações | G8: Impacto Financeiro | H8: Recomendações | I8: Tipo | J8: Tipo de Teste | K8: Tipo de Teste | L8: Julgamento Profissional
B9: V01 | C9: [P1] | D9: Pagamento sem documento fiscal | E9: =_xlfn.XLOOKUP($B9,'BASE DE PONTOS V+'!$B:$B,'BASE DE PONTOS V+'!$D:$D) -> Verificamos que ocorreram gastos sem a respectiva emissão de documento fiscal pelos fornecedores e/ou prestadores de serviços. | F9: =_xlfn.XLOOKUP($B9,'BASE DE PONTOS V+'!$B:$B,'BASE DE PONTOS V+'!$F:$F) -> Pagamentos sem os respectivos documentos fiscais dos fornecedores/prestadores de serviços não são permitidos pela legislação brasileira, assim como Convenção e Regimento Interno do Condomínio. Dessa forma, o mesmo pode ser multado e/ou sofrer outras penalidades impostas pelo fisco. | G9: =_xlfn.XLOOKUP(B9,'BASE DE PONTOS V+'!B:B,'BASE DE PONTOS V+'!E:E) -> 17679.82 | H9: =_xlfn.XLOOKUP($B9,'BASE DE PONTOS V+'!$B:$B,'BASE DE PONTOS V+'!$G:$G) -> Sugerimos que seja solicitado aos respectivos fornecedores/ prestadores de serviços a nota fiscal pelo fornecimento de material ou de prestação de serviço. | I9: =_xlfn.XLOOKUP($B9,'BASE DE PONTOS V+'!$B:$B,'BASE DE PONTOS V+'!$H:$H) -> Legal | J9: Voucher documental | K9: =_xlfn.XLOOKUP($B9,'BASE DE PONTOS V+'!$B:$B,'BASE DE PONTOS V+'!$M:$M) -> 0 | L9: =_xlfn.XLOOKUP(B9,'BASE DE PONTOS V+'!B:B,'BASE DE PONTOS V+'!J:J) -> Alto Impacto | M9: =_xlfn.XLOOKUP(D9,'BASE DE PONTOS V+'!C:C,'BASE DE PONTOS V+'!L:L) -> • 08/11/2022 • Novo ■ Vorcon Auditoria & Consultoria | N9: =IF(B9="","",IFERROR(IF(I9="Financeiro",VLOOKUP(G9,'BASE DA MATRIZ DE RISCOS'!$O$58:$Q$62,3,1),"Avaliar por julgameto"),"1")) -> Avaliar por julgameto
B10: V02 | C10: [P2] | D10: Pagamentos realizados sem os respectivos comprovantes de pagamento anexados | E10: =_xlfn.XLOOKUP($B10,'BASE DE PONTOS V+'!$B:$B,'BASE DE PONTOS V+'!$D:$D) -> Constatamos que alguns pagamentos foram realizados sem que fossem anexados os respectivos comprovantes de pagamentos ou documentos equivalentes dando a respectiva quitação. | F10: =_xlfn.XLOOKUP($B10,'BASE DE PONTOS V+'!$B:$B,'BASE DE PONTOS V+'!$F:$F) -> Possibilidade de pagamento duplicado dos valores, ou caso haja a solicitação dos comprovantes de pagamentos o Condomínio não os possua. | G10: =_xlfn.XLOOKUP(B10,'BASE DE PONTOS V+'!B:B,'BASE DE PONTOS V+'!E:E) -> 1558.24 | H10: =_xlfn.XLOOKUP($B10,'BASE DE PONTOS V+'!$B:$B,'BASE DE PONTOS V+'!$G:$G) -> Sugerimos que sejam criados controles para que os comprovantes de pagamentos estejam anexados com seus respectivos documentos. | I10: =_xlfn.XLOOKUP($B10,'BASE DE PONTOS V+'!$B:$B,'BASE DE PONTOS V+'!$H:$H) -> Financeiro | J10: Voucher documental | K10: =_xlfn.XLOOKUP($B10,'BASE DE PONTOS V+'!$B:$B,'BASE DE PONTOS V+'!$M:$M) -> 0 | L10: =_xlfn.XLOOKUP(B10,'BASE DE PONTOS V+'!B:B,'BASE DE PONTOS V+'!J:J) -> Baixo Impacto | M10: =_xlfn.XLOOKUP(D10,'BASE DE PONTOS V+'!C:C,'BASE DE PONTOS V+'!L:L) -> • 08/11/2022 • Novo ■ Vorcon Auditoria & Consultoria | N10: =IF(B10="","",IFERROR(IF(I10="Financeiro",VLOOKUP(G10,'BASE DA MATRIZ DE RISCOS'!$O$58:$Q$62,3,1),"Avaliar por julgameto"),"1")) -> 1
B11: V03 | C11: [P3] | D11: Negligência na gestão dos Documentos que compõe os Demonstrativos | E11: =_xlfn.XLOOKUP($B11,'BASE DE PONTOS V+'!$B:$B,'BASE DE PONTOS V+'!$D:$D) -> Verificamos que alguns comprovantes não estão sendo arquivados com os cuidados necessários, com isso alguns estão ilegíveis. | F11: =_xlfn.XLOOKUP($B11,'BASE DE PONTOS V+'!$B:$B,'BASE DE PONTOS V+'!$F:$F) -> Possível dificuldade e/ou impossibilidade na visualização dos gastos e dúvidas quanto a possíveis consultas no futuro em função do estado dos documentos. | G11: =_xlfn.XLOOKUP(B11,'BASE DE PONTOS V+'!B:B,'BASE DE PONTOS V+'!E:E) -> 118.82 | H11: =_xlfn.XLOOKUP($B11,'BASE DE PONTOS V+'!$B:$B,'BASE DE PONTOS V+'!$G:$G) -> Sugerimos aperfeiçoamento dos controles internos para que no momento do recebimento das documentações sejam retiradas as cópias ou ocorram as digitalizações visando preservar as informações. | I11: =_xlfn.XLOOKUP($B11,'BASE DE PONTOS V+'!$B:$B,'BASE DE PONTOS V+'!$H:$H) -> Operacional | J11: Voucher documental | K11: =_xlfn.XLOOKUP($B11,'BASE DE PONTOS V+'!$B:$B,'BASE DE PONTOS V+'!$M:$M) -> 0 | L11: =_xlfn.XLOOKUP(B11,'BASE DE PONTOS V+'!B:B,'BASE DE PONTOS V+'!J:J) -> Baixo Impacto | M11: =_xlfn.XLOOKUP(D11,'BASE DE PONTOS V+'!C:C,'BASE DE PONTOS V+'!L:L) -> • 08/11/2022 • Novo ■ Vorcon Auditoria & Consultoria | N11: =IF(B11="","",IFERROR(IF(I11="Financeiro",VLOOKUP(G11,'BASE DA MATRIZ DE RISCOS'!$O$58:$Q$62,3,1),"Avaliar por julgameto"),"1")) -> Avaliar por julgameto
B12: V04 | C12: [P4] | D12: Conjunto de documentos anexados fora do mês correspondente no Balancete. | E12: =_xlfn.XLOOKUP($B12,'BASE DE PONTOS V+'!$B:$B,'BASE DE PONTOS V+'!$D:$D) -> Desorganização da documentação suporte dificultam a análise de todas as partes envolvidas. | F12: =_xlfn.XLOOKUP($B12,'BASE DE PONTOS V+'!$B:$B,'BASE DE PONTOS V+'!$F:$F) -> A ausência de apresentação de forma tempestiva dos documentos financeiros poderá afetar diretamente o fluxo de caixa e o controle do financeiro do condomínio. | G12: =_xlfn.XLOOKUP(B12,'BASE DE PONTOS V+'!B:B,'BASE DE PONTOS V+'!E:E) -> 418.07 | H12: =_xlfn.XLOOKUP($B12,'BASE DE PONTOS V+'!$B:$B,'BASE DE PONTOS V+'!$G:$G) -> Recomendamos que a prestação de contas seja realizada conforme o período correspondente as despesas. | I12: =_xlfn.XLOOKUP($B12,'BASE DE PONTOS V+'!$B:$B,'BASE DE PONTOS V+'!$H:$H) -> Operacional | J12: Voucher documental | K12: =_xlfn.XLOOKUP($B12,'BASE DE PONTOS V+'!$B:$B,'BASE DE PONTOS V+'!$M:$M) -> 0 | L12: =_xlfn.XLOOKUP(B12,'BASE DE PONTOS V+'!B:B,'BASE DE PONTOS V+'!J:J) -> Baixo Impacto | M12: =_xlfn.XLOOKUP(D12,'BASE DE PONTOS V+'!C:C,'BASE DE PONTOS V+'!L:L) -> • 08/11/2022 • Novo ■ Vorcon Auditoria & Consultoria | N12: =IF(B12="","",IFERROR(IF(I12="Financeiro",VLOOKUP(G12,'BASE DA MATRIZ DE RISCOS'!$O$58:$Q$62,3,1),"Avaliar por julgameto"),"1")) -> Avaliar por julgameto
B13: V05 | C13: [P5] | D13: Informações apresentado fora do mês correspondente na demonstração financeira. | E13: =_xlfn.XLOOKUP($B13,'BASE DE PONTOS V+'!$B:$B,'BASE DE PONTOS V+'!$D:$D) -> Verificamos que há desorganização das informações na demonstração financeira que dificultam na análise de todas as partes envolvidas. | F13: =_xlfn.XLOOKUP($B13,'BASE DE PONTOS V+'!$B:$B,'BASE DE PONTOS V+'!$F:$F) -> A falta de apresentação de maneira tempestiva das informações financeiras poderá afetar diretamente o controle financeiro do condomínio e o entendimento dos Demonstrativos. | G13: =_xlfn.XLOOKUP(B13,'BASE DE PONTOS V+'!B:B,'BASE DE PONTOS V+'!E:E) -> 418.07 | H13: =_xlfn.XLOOKUP($B13,'BASE DE PONTOS V+'!$B:$B,'BASE DE PONTOS V+'!$G:$G) -> Indicamos que as informações apresentadas nas Demonstrações Financeiras sejam realizadas conforme o período correspondente. | I13: =_xlfn.XLOOKUP($B13,'BASE DE PONTOS V+'!$B:$B,'BASE DE PONTOS V+'!$H:$H) -> Financeiro | J13: Voucher documental | K13: =_xlfn.XLOOKUP($B13,'BASE DE PONTOS V+'!$B:$B,'BASE DE PONTOS V+'!$M:$M) -> 0 | L13: =_xlfn.XLOOKUP(B13,'BASE DE PONTOS V+'!B:B,'BASE DE PONTOS V+'!J:J) -> Baixo Impacto | M13: =_xlfn.XLOOKUP(D13,'BASE DE PONTOS V+'!C:C,'BASE DE PONTOS V+'!L:L) -> • 08/11/2022 • Novo ■ Vorcon Auditoria & Consultoria | N13: =IF(B13="","",IFERROR(IF(I13="Financeiro",VLOOKUP(G13,'BASE DA MATRIZ DE RISCOS'!$O$58:$Q$62,3,1),"Avaliar por julgameto"),"1")) -> 1
B14: V07 | C14: [P6] | D14: Diferenças entre: Valor do comprovante de pagamento X Valor da documentação suporte. | E14: =_xlfn.XLOOKUP($B14,'BASE DE PONTOS V+'!$B:$B,'BASE DE PONTOS V+'!$D:$D) -> Verificamos que alguns pagamentos foram realizados após a data de vencimento acarretando em gastos adicionais. | F14: =_xlfn.XLOOKUP($B14,'BASE DE PONTOS V+'!$B:$B,'BASE DE PONTOS V+'!$F:$F) -> Possibilidade do condomínio incorrer em gastos desnecessários | G14: =_xlfn.XLOOKUP(B14,'BASE DE PONTOS V+'!B:B,'BASE DE PONTOS V+'!E:E) -> 10.37 | H14: =_xlfn.XLOOKUP($B14,'BASE DE PONTOS V+'!$B:$B,'BASE DE PONTOS V+'!$G:$G) -> Sugerimos que seja elaborado um controle de vencimento das despesas e que sejam efetuados os pagamentos até o vencimento. | I14: =_xlfn.XLOOKUP($B14,'BASE DE PONTOS V+'!$B:$B,'BASE DE PONTOS V+'!$H:$H) -> Financeiro | J14: Voucher documental | K14: =_xlfn.XLOOKUP($B14,'BASE DE PONTOS V+'!$B:$B,'BASE DE PONTOS V+'!$M:$M) -> 0 | L14: =_xlfn.XLOOKUP(B14,'BASE DE PONTOS V+'!B:B,'BASE DE PONTOS V+'!J:J) -> Baixo Impacto | M14: =_xlfn.XLOOKUP(D14,'BASE DE PONTOS V+'!C:C,'BASE DE PONTOS V+'!L:L) -> • 08/11/2022 • Novo ■ Vorcon Auditoria & Consultoria | N14: =IF(B14="","",IFERROR(IF(I14="Financeiro",VLOOKUP(G14,'BASE DA MATRIZ DE RISCOS'!$O$58:$Q$62,3,1),"Avaliar por julgameto"),"1")) -> 1
B15: V08 | C15: [P7] | D15: Pagamentos realizados antes da emissão da nota fiscal. | E15: =_xlfn.XLOOKUP($B15,'BASE DE PONTOS V+'!$B:$B,'BASE DE PONTOS V+'!$D:$D) -> Verificamos que ocorreram pagamentos onde a emissão da documentação fiscal é posterior a data em que a transação bancária foi realizada. | F15: =_xlfn.XLOOKUP($B15,'BASE DE PONTOS V+'!$B:$B,'BASE DE PONTOS V+'!$F:$F) -> O pagamento antes da emissão das notas fiscais traz uma vulnerabilidade a respeito do cumprimento das melhores práticas de gestão podendo gerar penalidades tributárias. | G15: =_xlfn.XLOOKUP(B15,'BASE DE PONTOS V+'!B:B,'BASE DE PONTOS V+'!E:E) -> 3563.16 | H15: =_xlfn.XLOOKUP($B15,'BASE DE PONTOS V+'!$B:$B,'BASE DE PONTOS V+'!$G:$G) -> Recomendamos que seja verificada a emissão da nota fiscal antes da realização do pagamento. | I15: =_xlfn.XLOOKUP($B15,'BASE DE PONTOS V+'!$B:$B,'BASE DE PONTOS V+'!$H:$H) -> Legal | J15: Voucher documental | K15: =_xlfn.XLOOKUP($B15,'BASE DE PONTOS V+'!$B:$B,'BASE DE PONTOS V+'!$M:$M) -> 0 | L15: =_xlfn.XLOOKUP(B15,'BASE DE PONTOS V+'!B:B,'BASE DE PONTOS V+'!J:J) -> médio impacto | M15: =_xlfn.XLOOKUP(D15,'BASE DE PONTOS V+'!C:C,'BASE DE PONTOS V+'!L:L) -> • 08/11/2022 • Novo ■ Vorcon Auditoria & Consultoria | N15: =IF(B15="","",IFERROR(IF(I15="Financeiro",VLOOKUP(G15,'BASE DA MATRIZ DE RISCOS'!$O$58:$Q$62,3,1),"Avaliar por julgameto"),"1")) -> Avaliar por julgameto
B16: V10 | C16: [P8] | D16: Os balancetes sem aprovação dos conselheiros fiscais e do síndico no termo de aprovação. | E16: No período de 03/2021 a 02/2022 não constam as assinaturas do síndico e dos conselheiros fiscais para aprovação dos balancetes. Porém, conforme a Convenção do Subcondomínio Reserva das Plantas na cláusula 4.9.1 - f) "O Síndico de cada Subcondomínio tem as seguintes atribuições [...] rubrica[...] dos livros". Além disso, no item G-4.21-c) "Cada Conselho Fiscal [...] terá as seguintes atribuições: emitir parecer sobre as contas [...] do Síndico do Subcondomínio Residencial [...], conferindo-as, aprovando-as ou rejeitando-as". | F16: A falta das assinaturas dos conselheiros fiscais nos termos de aprovação dos balancetes indica que as contas do condomínio não foram submetidas ao exame, podendo acarretar a redução do nível de confiança dos demonstrativos e prejudicar a leitura dos usuários. | G16: NA | H16: Sugerimos que os conselheiros fiscais realizem o exame dos balancetes e caso ocorra a aprovação dos mesmos, confirmem com as suas assinaturas nos termos de aprovação. Mesmo com as demonstrações financeiras sendo auditadas mensalmente, é necessário a validação do conselho fiscal. | I16: Legal | J16: Resumo Convenção | K16: 0 | L16: Alto Impacto | M16: • 08/11/2022 • Novo ■ Vorcon Auditoria & Consultoria | N16: Avaliar por julgameto
B17: V11 | C17: [P9] | D17: Falta de registro de Ata's em cartório | E17: Não identificamos o registro em cartório das Ata's: 16/12/2021, 09/09/2021, 14/10/2021, 27/01/2022, 03/02/2022. Conforme a Convenção do Subcondomínio Reserva das Plantas na cláusula 4.9.1 - f) "O Síndico de cada Subcondomínio tem as seguintes atribuições [...] Providenciar abertura, numeração, rubrica e encerramento dos livros, bem como o registro das atas em Cartório de Registro de Títulos e Documentos". | F17: Possível questionamento dos Condominos quanto a validação das Ata's por falta de registo no cartório. | G17: NA | H17: Sugerimos que haja registro das Ata's em cartório, conforme convenção. | I17: Legal | J17: Resumo Convenção | K17: 0 | L17: médio impacto | M17: • 08/11/2022 • Novo ■ Vorcon Auditoria & Consultoria | N17: Avaliar por julgameto
B18: V12 | C18: [P10] | D18: Falta relatório de auditoria do período anterior. | E18: Conforme a Convenção do Subcondomínio Reserva das Plantas na cláusula 4.9.1 - h) "O Síndico de cada Subcondomínio tem as seguintes atribuições [...] Contratar, anualmente, empresa de auditoria para fiscalizar as contas do Subcondomínio." Dessa forma, não foi identificado o relatório da auditoria do período que antecedeu a auditoria atual (03/2021 a 02/2022). No entanto, analisamos conforme entendimento com o cliente que o condomínio realizou a auditoria em 2021 e não receberam o relatório. | F18: A ausência de contratação da auditoria e apresentação do relatório em relação ao período anterior, além de infringir a convenção condomonial, prejudica a transparência na prestação de contas podendo causar danos a situação financeira, econômica, legal e imagem da entidade. | G18: NA | H18: Recomendamos que a administração sempre realize auditorias preventivas. | I18: Estratégico | J18: Follow Up CCI | K18: 0 | L18: Alto Impacto | M18: • 08/11/2022 • Novo ■ Vorcon Auditoria & Consultoria | N18: Avaliar por julgameto
B19: V13 | C19: [P11] | D19: Falta de Planejamento Orçamentário Anual | E19: Conforme a Convenção do Subcondomínio Reserva das Plantas na cláusula 4.36.1 "A assembleia geral ordinária do Condomínio realizar-se-á anualmente [...] outra assembleia geral ordinária do CONDOMÍNIO [Sic], sempre até o final do mês de novembro de cada ano e a ela competirá especificamente fixar o orçamento anual do CONDOMÍNIO para o exercicio social vindouro e a forma de cobrança das respectivas despesas." Dessa forma, não foi identificado o Planejamento Orçamentário para o ano de 2021. Além disso, identificamos nas Atas que o Sr. Marco Ribeiro, demonstrou as prinipais causas do aumento das despesas e informou que o condomíno está lidando com o mesmo planejamento orçamentário há 03 anos e que com a pandemia, todos os produtos e serviços tem sofrido aumentos fora do comum. | F19: A falta da elaboração do planejamento orçamentário poderá prejudicar o controle das contas condominiais e a prevenção dos gastos desnecerrários ou demasiados. | G19: NA | H19: Recomendamos que o o planejamento orçamentário ocorra dentro do período previsto em convenção. | I19: Estratégico | J19: Orçado X Realizado | K19: 0 | L19: Alto Impacto | M19: • 08/11/2022 • Novo ■ Vorcon Auditoria & Consultoria | N19: Avaliar por julgameto
B20: V14 | C20: [P12] | D20: Sistema de medição da água realizado de forma não individualizada | E20: Segundo a ATA Reunião de Moradores do dia 09/09/2021 o "Sr. Roque Andrade entrou na tratativa da individualização da água e falou sobre os benefícios que isso traria por conta do consumo desigual entre as unidades [...]". Dessa forma, identificamos que o sistema de medição da água não é realizado de forma individualizada, infringindo assim, a cláusula 15.1 - e) da Convenção Condominial. | F20: A infração em relação a item previsto na Convenção Condominial pode gerar questionamentos, reclamações, impactos em relação a sustentabilidade e prejuizos de ordem legal para o condominio. | G20: NA | H20: Recomendamos que a administração analise a viabilidade da individualização de medição da água junto aos condominos e profissionais técnicos. Após isso, se for viável planeje a implementação e caso contrário, atualize a convenção para modificar a previsão desse item. | I20: Legal | J20: Resumo Convenção | K20: 0 | L20: médio impacto | M20: • 08/11/2022 • Novo ■ Vorcon Auditoria & Consultoria | N20: Avaliar por julgameto
B21: V15 | C21: [P13] | D21: Valor apresentado no comprovante de pagamento, mas que não consta no extrato bancário | E21: Identificamos comprovante de pagamento do dia 19/10/2021 informando que foi realizado o pagamento no valor de R$ 1000,00 através da Agência: 4306 e Conta: 130035030. No entanto, essas informações não constam no extrato bancário dessa respectiva conta. | F21: A divergência de informações entre comprovante de pagamento e o extrato bancário pode indicar erro ou fraude na gestão financeira condominial e impactar nas disponibilidades da entidade. | G21: 1000 | H21: Indicamos que a Administração promova melhorias em seus controles interno tendo como finalidade a apresentação de informações financeiras convergentes com os registros expostos nos extratos bancários. | I21: Financeiro | J21: Demonstrativo Financeiro + voucher nos extratos | K21: 0 | L21: Baixo Impacto | M21: #N/A | N21: 1
B22: V16 | C22: [P14] | D22: Falta de apresentação de extratos bancários | E22: Verificamos que em alguns meses não foram apresentados à auditoria os extratos do Banco Santander, agência: 4306 e contas: 13.003502-3 / 13.003496-7, além das aplicações financeiras. | F22: A falta dos extratos bancários prejudica a análise das informações, o entendimento e a validação das entradas e saídas financeiras do condomínio. | G22: NA | H22: Visando aumentar a transparência na prestação de contas do condomínio, sugerimos à Administração que envie os extratos bancários emitidos diretamente pelas instituições financeiras para que as análises dessas informações se tornem possíveis. | I22: Financeiro | J22: Demonstrativo Financeiro + voucher nos extratos | K22: 0 | L22: Baixo Impacto | M22: • 08/11/2022 • Novo ■ Vorcon Auditoria & Consultoria | N22: 1
B23: V17 | C23: [P15] | D23: Saídas nos extratos não validados com a voucher | E23: Identificamos no momento do confronto entre os extratos bancários e a Voucher Documental produzida com as informações apresentadas pelo condomínio, a existência de saídas de recursos dos extratos que não constam na Voucher. Diante disso, não ocorre a verificação dos documentos comprobatórios dos respectivos dispêndios realizados pelo condomínio | F23: As saídas de recursos dos extratos sem a validação da Voucher Documental poderão prejudicar a transparência e afetar a prestação de contas, dando oportunidade de os valores não serem utilizados para fins que geram benefícios econômicos ao condomínio. | G23: 2117.99 | H23: Indicamos ao Conselho Fiscal a estruturação de procedimentos de controles internos que garantam destinação adequada dos recursos condominiais sendo apresentados todos os documentos comprobatórios da realização de suas despesas e validados por uma auditoria contínua. | I23: Financeiro | J23: Demonstrativo Financeiro + voucher nos extratos | K23: 0 | L23: Baixo Impacto | M23: • 08/11/2022 • Novo ■ Vorcon Auditoria & Consultoria | N23: 1
B24: V18 | C24: [P16] | D24: Apresentação incompleta de extrato bancário | E24: Recebemos o extrato do Banco Santander, agência: 4306 e conta: 13.003503-0 referente ao mês 02/2022 de forma incompleta, impossibilitando assim, a conferência de todas as suas informações. | F24: A entrega de extrato realizada de forma incompleta impede a análise, o entendimento e a validação das entradas e saídas financeiras, reduzindo assim, a transparência nas prestação de contas do condomínio. | G24: NA | H24: Recomendamos à Administração que envie os extratos bancários emitidos diretamente pelas instituições financeiras contemplando todas as informações do período solicitado. | I24: Financeiro | J24: Demonstrativo Financeiro + voucher nos extratos | K24: 0 | L24: Baixo Impacto | M24: • 08/11/2022 • Novo ■ Vorcon Auditoria & Consultoria | N24: 1
B25: V19 | C25: [P17] | D25: Diferenças entre os saldos dos Demonstrativos Financeiros de Receitas e Despesas em relação a Demonstração dos Saldos Financeiros. | E25: Verificamos os saldos finais dos demonstrativos financeiros de receitas e despesas (DF) e confrontamos com os valores finais dos demonstrativos dos saldos financeiros (DSF), nos quais foram identificadas divergências. | F25: A apresentação dos saldos divergentes nos demonstrativos financeiros de receita e despesas, poderá prejudicar a transparência e afetar a prestação de contas comprometendo a interpretação dos usuários das informações financeiras do condomínio. | G25: 109 | H25: Recomendamos que os demonstrativos dos saldos financeiros assim como os demonstrativo de receita e despesas sejam revisados para reduzir os riscos de divergências. | I25: Financeiro | J25: Conciliação Bancária + Elaboração dos quadros dos Demonstrativos Financeiros | K25: 0 | L25: Baixo Impacto | M25: • 08/11/2022 • Novo ■ Vorcon Auditoria & Consultoria | N25: 1
B26: V20 | C26: [P18] | D26: Ausência de apresentação de mapa de cotação | E26: Verificamos que algumas compras realizadas não estavam sendo efetuado o mapa de cotação. | F26: A falta da cotação mínima de 3 orçamentos poderá prejudicar o condomínio através de aquisições de bens e/ou serviços de baixa qualidade, com fornecedores sem conhecimento ou respaldo técnico e entregas diferente do escopo esperado. | G26: NA | H26: Recomendamos a administração que seja realizado mapa de orçamento no mínimo de 3 cotações para as aquisições dos bens ou serviços do condomínio. | I26: Operacional | J26: Voucher documental | K26: 0 | L26: Baixo Impacto | M26: • 08/11/2022 • Novo ■ Vorcon Auditoria & Consultoria | N26: Avaliar por julgameto
B27: V21 | C27: [P19] | D27: Ausência de inventário dos ativos imobilizados | E27: Não identificamos o controle patrimonial dos ativos imobilizados para atualização do saldo em decorrência dos bens adquiridos, obsoletos e/ou perdidos para realização da baixa, assim como as depreciações. | F27: A ausência do controle patrimonial do condomínio poderá impactar em possíveis perdas ou desvios do ativo imobilizado. | G27: NA | H27: Sugerimos que à Administração do condomínio busque realizar o inventário dos ativos imobilizados anualmente. | I27: Financeiro | J27: Inspeção estatística dos itens do Imobilizado | K27: 0 | L27: Alto Impacto | M27: • 08/11/2022 • Novo ■ Vorcon Auditoria & Consultoria | N27: 1
B28: V22 | C28: [P20] | D28: Inexistência de valor estimado dos honorários advocatícios | E28: Não identificamos o valor estimado da expectativa de exito nos casos de processos onde o condomínio esteja como polo ativo ou passivo para período de 03/2021 até 02/2022 | F28: 0 | G28: N/A | H28: 0 | I28: Financeiro | J28: Teste de Contingência | K28: 0 | L28: médio impacto | M28: #N/A | N28: 1
B29: V23 | C29: [P21] | D29: Perda Possível de Causa Judicial | E29: Identificamos no período de 28 de fevereiro 2022 a perda possível de R$ 406.946,20. Salientamos que a Perda Possível é aquela que o condomínio tem ou não uma obrigação presente legal como resultado de evento passado que haverá uma saída de recursos para liquidar essa obrigação. | F29: 0 | G29: 396946.2 | H29: 0 | I29: Legal | J29: Teste de Contingência | K29: 0 | L29: Alto Impacto | M29: • 08/11/2022 • Novo ■ Vorcon Auditoria & Consultoria | N29: Avaliar por julgameto
B30: V24 | C30: [P22] | D30: Perda Provável de Causa Judicial | E30: Identificamos no período de 28 de fevereiro 2022, uma perda provável de R$ 32.000,00 referente ao processo de FELIPE FERREIRA OLIVEIRA X SUBCONDOMÍNIO RESERVA DAS PLANTAS, tendo como objeto AÇÃO DECLARATÓRIA E INDENIZATÓRIA. Salientamos que a perda provável é quando o condomínio tem uma obrigação presente legal como resultado de evento passado e seja provável que será necessária a saída de recurso para liquidar a obrigação. Nesse sentido, a perda da causa judicial é mais provável que sim do que não. | F30: 0 | G30: 32000 | H30: Recomendamos que seja realizado uma Provisão para Perda .... | I30: Financeiro | J30: Teste de Contingência | K30: 0 | L30: médio impacto | M30: • 08/11/2022 • Novo ■ Vorcon Auditoria & Consultoria | N30: 2
B31: V25 | C31: [P23] | D31: Perda Remota de Causa Judicial | E31: Identificamos no período de 28 de fevereiro 2022, uma perda Remota de R$ 1.503.630,42. Salientamos que a perda remota é quando o condomínio não tem uma obrigação presente legal como resultado de evento passado e seja remoto que haverá uma saída de recurso para liquidar essa obrigação. Nesse sentido, a perda da causa judicial é menos provável que sim do que não. | F31: 0 | G31: 1503630.4 | H31: 0 | I31: Legal | J31: Teste de Contingência | K31: 0 | L31: médio impacto | M31: • 08/11/2022 • Novo ■ Vorcon Auditoria & Consultoria | N31: Avaliar por julgameto
B32: V26 | C32: [P24] | D32: Ausência de registro do Regimento do condomínio em cartório. | E32: Não foi possível validar a data do registro do condomínio no cartório a partir do documento recebido. | F32: A falta de registro em cartório do Regimento do Condomínio poderá gerar problemas relacionados a validade jurídica da documentação. | G32: NA | H32: Sugerimos que o Regimento seja registrado em cartório. | I32: Legal | J32: Regimento Interno | K32: 0 | L32: Baixo Impacto | M32: • 08/11/2022 • Novo ■ Vorcon Auditoria & Consultoria | N32: Avaliar por julgameto
B33: V27 | C33: [P25] | D33: Impossibilidade de identificação da conclusão da Obra do Parquinho e seu pagamento. | E33: Analisamos as Atas e os demonstrativos financeiros e identificamos a obra do parquinho pela empresa Danielson Alcantra Contruções e Reformas de 16/11/2021. Porém, não identificamos a ATA com informação de prestação de serviço concluída, como também, não localizamos o pagamento referente a terceira parcela do serviço prestado. | F33: 0 | G33: N/A | H33: 0 | I33: Operacional | J33: Resumo das Atas | K33: 0 | L33: Baixo Impacto | M33: #N/A | N33: Avaliar por julgameto
B34: V28 | C34: [P26] | D34: Falta de questionamentos do Conselho Fiscal nas Assembleias | E34: Analisamos 100% das atas de reuniões, Assembleia Geral Extraordinária (AGE), Assembleia Geral Ordinária (AGO), Conselho de Administração, Conselho Fiscal e outras atas de reuniões formalizadas do período de de 01/03/2021 a 28/02/2022 e não identificamos a fala do conselho fiscal. Inclusive, foi mencionado na AGE 28/10/2021 que o Conselho Consultivo foi o único a realizar a seleção para a eleição do síndico duas vezes sem a participação do Conselho Fiscal. | F34: 0 | G34: N/A | H34: 0 | I34: Legal | J34: Resumo das Atas | K34: 0 | L34: Alto Impacto | M34: • 08/11/2022 • Novo ■ Vorcon Auditoria & Consultoria | N34: Avaliar por julgameto
B35: V29 | C35: [P27] | D35: Cargo de Síndico Interino e de Conselheiro Fiscal ocupado pelo mesmo condômino | E35: Conforme a Convenção do Subcondomínio Reserva das Plantas na item G - 4.21 c) "Cada Conselho Fiscal [...] terá as seguintes atribuições: emitir parecer sobre as contas [...] do Síndico do Subcondomínio Residencial [...], conferindo-as, aprovando-as ou rejeitando-as" e também o segundo o Código Civil no Art. 1.356 "Poderá haver no condomínio um conselho fiscal [...]ao qual compete dar parecer sobre as contas do síndico". Dessa forma, analisamos 100% das atas e identificamos na AGE de 28/10/2021 que o Sr. Roque da Silva Pereira Andrade do Prédio Vitórioa Régia, 907 ocupa os cargos de Síndico Interino e Conselheiro fiscal ao mesmo tempo. | F35: Os dois cargos ocupado pelo condômino Sr. Roque da Silva ao mesmo tempo, pode afetar a independência do Conselho Fiscal em relação aos atos do Síndico Interino, influenciando o julgamento profissional do conselho e permitindo que o mesmo não atue com integridade, objetividade e ceticismo conforme NBC PA 400. | G35: N/A | H35: Recomendamos que a Administração do Condomínio promova melhorias nos seus controles internos e que não seja permitido que uma mesma pessoa ocupa os cargos de Síndico e Conselheiros simultaneamente. | I35: Estratégico | J35: Resumo das Atas | K35: 0 | L35: Alto Impacto | M35: • 08/11/2022 • Novo ■ Vorcon Auditoria & Consultoria | N35: Avaliar por julgameto
B36: V30 | C36: [P28] | D36: Inexistência da ATA do Conselho Consultivo na Assembleia Geral Extraordinária | E36: Conforme a Convenção do Subcondomínio Reserva das Plantas o síndico necessita obrigatoriamente ter a relação de todas as atas bem como o seu registro. Dessa forma, analisamos 100% das atas e identificamos na AGE de 28/10/2021 que conforme o síndico e o Gerente a ATA de Reunião do Conselho Consultivo não existia na Administradora no dia da Assembleia Geral Extraordinária. Assim, a ata não foi apresentada para o Advogado e por essa razão, o processo discutido pelo Conselho consultivo ficou nulo para a Assembleia Geral Extraordinária. | F36: 0 | G36: N/A | H36: 0 | I36: Legal | J36: Resumo das Atas | K36: 0 | L36: médio impacto | M36: • 08/11/2022 • Novo ■ Vorcon Auditoria & Consultoria | N36: Avaliar por julgameto
B37: V31 | C37: [P29] | D37: Impacto significativo com os inadimplentes | E37: Mês 02/2022 | F37: 0 | G37: 598391.24 | H37: 0 | I37: Financeiro | J37: Teste de Inadimplência | K37: 0 | L37: Alto Impacto | M37: #N/A | N37: 5
M45: =_xlfn.XLOOKUP(D45,'BASE DE PONTOS V+'!C:C,'BASE DE PONTOS V+'!L:L) -> 0 | N45: =IF(B45="","",IFERROR(IF(I45="Financeiro",VLOOKUP(G45,'BASE DA MATRIZ DE RISCOS'!$O$58:$Q$62,3,1),"Avaliar por julgameto"),"1"))
M46: =_xlfn.XLOOKUP(D46,'BASE DE PONTOS V+'!C:C,'BASE DE PONTOS V+'!L:L) -> 0 | N46: =IF(B46="","",IFERROR(IF(I46="Financeiro",VLOOKUP(G46,'BASE DA MATRIZ DE RISCOS'!$O$58:$Q$62,3,1),"Avaliar por julgameto"),"1"))
M47: =_xlfn.XLOOKUP(D47,'BASE DE PONTOS V+'!C:C,'BASE DE PONTOS V+'!L:L) -> 0 | N47: =IF(B47="","",IFERROR(IF(I47="Financeiro",VLOOKUP(G47,'BASE DA MATRIZ DE RISCOS'!$O$58:$Q$62,3,1),"Avaliar por julgameto"),"1"))
M48: =_xlfn.XLOOKUP(D48,'BASE DE PONTOS V+'!C:C,'BASE DE PONTOS V+'!L:L) -> 0 | N48: =IF(B48="","",IFERROR(IF(I48="Financeiro",VLOOKUP(G48,'BASE DA MATRIZ DE RISCOS'!$O$58:$Q$62,3,1),"Avaliar por julgameto"),"1"))
M49: =_xlfn.XLOOKUP(D49,'BASE DE PONTOS V+'!C:C,'BASE DE PONTOS V+'!L:L) -> 0 | N49: =IF(B49="","",IFERROR(IF(I49="Financeiro",VLOOKUP(G49,'BASE DA MATRIZ DE RISCOS'!$O$58:$Q$62,3,1),"Avaliar por julgameto"),"1"))

Sheet Planilha1
B2: Ponto de Controle | C2: Título | D2: Tipo | E2: Tipo | F2: Probabilidade | G2: Perdas/ | H2: Exposição | I2: Setor | J2: Classificação por Pontuação
G3: Impacto
B4: [P1] | C4: Pagamento sem documento fiscal | D4: Legal | E4: 3 | F4: 4 | G4: 2 | H4: 24 | I4: Voucher documental | J4: BAIXO IMPACTO
B5: [P2] | C5: Pagamentos realizados sem os respectivos comprovantes de pagamento anexados | D5: Financeiro | E5: 5 | F5: 3 | G5: 1 | H5: 15 | I5: Voucher documental | J5: BAIXO IMPACTO
B6: [P3] | C6: Negligência na gestão dos Documentos que compõe os Demonstrativos | D6: Operacional | E6: 4 | F6: 3 | G6: 1 | H6: 12 | I6: Voucher documental | J6: BAIXO IMPACTO
B7: [P4] | C7: Conjunto de documentos anexados fora do mês correspondente no Balancete. | D7: Operacional | E7: 4 | F7: 1 | G7: 1 | H7: 4 | I7: Voucher documental | J7: BAIXO IMPACTO
B8: [P5] | C8: Informações apresentado fora do mês correspondente na demonstração financeira. | D8: Financeiro | E8: 5 | F8: 1 | G8: 1 | H8: 5 | I8: Voucher documental | J8: BAIXO IMPACTO
B9: [P6] | C9: Diferenças entre: Valor do comprovante de pagamento X Valor da documentação suporte. | D9: Financeiro | E9: 5 | F9: 3 | G9: 1 | H9: 15 | I9: Voucher documental | J9: BAIXO IMPACTO
B10: [P7] | C10: Pagamento realizado após data de vencimento com incidência de multa e juros. | D10: Financeiro | E10: 5 | F10: 2 | G10: 1 | H10: 10 | I10: Voucher documental | J10: BAIXO IMPACTO
B11: [P8] | C11: Pagamentos realizados antes da emissão da nota fiscal. | D11: Legal | E11: 3 | F11: 3 | G11: 1 | H11: 9 | I11: Voucher documental | J11: BAIXO IMPACTO
B12: [P9] | C12: Emissão de nota de simples remessa após o pagamento do produto. | D12: Financeiro | E12: 5 | F12: 1 | G12: 1 | H12: 5 | I12: Voucher documental | J12: BAIXO IMPACTO
B13: [P10] | C13: Os balancetes sem aprovação dos conselheiros fiscais e do síndico no termo de aprovação. | D13: Legal | E13: 3 | F13: 5 | G13: 4 | H13: 60 | I13: Resumo Convenção | J13: MÉDIO IMPACTO
B14: [P11] | C14: Falta de registro de Ata's em cartório | D14: Legal | E14: 3 | F14: 5 | G14: 4 | H14: 60 | I14: Resumo Convenção | J14: MÉDIO IMPACTO
B15: [P12] | C15: Falta relatório de auditoria do período anterior. | D15: Estratégico | E15: 4 | F15: 5 | G15: 4 | H15: 80 | I15: Follow Up CCI | J15: ALTO IMPACTO
... B34: [P31] | C34: Impacto significativo com os inadimplentes | D34: Financeiro | E34: 5 | F34: 5 | G34: 5 | H34: 125 | I34: Teste de Inadimplência | J34: ALTO IMPACTO

Sheet BASE DE PONTOS V+
B2: Condomínio Reserva das Plantas
B3: BASE DE PONTOS V+
B4: Data base:
B6: 2 | C6: 2 | H6: 7 | I6: 8 | J6: 8 | K6: 8 | M6: 8
B7: V+ | C7: Descrição Resumida | D7: Descrição | E7: Impacto Financeiro | F7: Riscos e Impactos | G7: Recomendação | H7: Tipo | I7: Tipo de Teste | J7: Julgamento | K7: Tipo de Teste | L7: x | M7: Tipo de Teste
B8: V01 | C8: Pagamento sem documento fiscal | D8: Verificamos que ocorreram gastos sem a respectiva emissão de documento fiscal pelos fornecedores e/ou prestadores de serviços. | E8: 17679.82 | F8: Pagamentos sem os respectivos documentos fiscais dos fornecedores/prestadores de serviços não são permitidos pela legislação brasileira, assim como Convenção e Regimento Interno do Condomínio. Dessa forma, o mesmo pode ser multado e/ou sofrer outras penalidades impostas pelo fisco. | G8: Sugerimos que seja solicitado aos respectivos fornecedores/ prestadores de serviços a nota fiscal pelo fornecimento de material ou de prestação de serviço. | H8: Legal | I8: 6 - 01.1.6 - CRP - Voucher documental - 01.03.2021 a 28.02.2022 | J8: Alto Impacto | L8: • 08/11/2022 • Novo ■ Vorcon Auditoria & Consultoria
B9: V02 | C9: Pagamentos realizados sem os respectivos comprovantes de pagamento anexados | D9: Constatamos que alguns pagamentos foram realizados sem que fossem anexados os respectivos comprovantes de pagamentos ou documentos equivalentes dando a respectiva quitação. | E9: 1558.24 | F9: Possibilidade de pagamento duplicado dos valores, ou caso haja a solicitação dos comprovantes de pagamentos o Condomínio não os possua. | G9: Sugerimos que sejam criados controles para que os comprovantes de pagamentos estejam anexados com seus respectivos documentos. | H9: Financeiro | I9: 6 - 01.1.6 - CRP - Voucher documental - 01.03.2021 a 28.02.2022 | J9: Baixo Impacto | L9: • 08/11/2022 • Novo ■ Vorcon Auditoria & Consultoria
B10: V03 | C10: Negligência na gestão dos Documentos que compõe os Demonstrativos | D10: Verificamos que alguns comprovantes não estão sendo arquivados com os cuidados necessários, com isso alguns estão ilegíveis. | E10: 118.82 | F10: Possível dificuldade e/ou impossibilidade na visualização dos gastos e dúvidas quanto a possíveis consultas no futuro em função do estado dos documentos. | G10: Sugerimos aperfeiçoamento dos controles internos para que no momento do recebimento das documentações sejam retiradas as cópias ou ocorram as digitalizações visando preservar as informações. | H10: Operacional | I10: 6 - 01.1.6 - CRP - Voucher documental - 01.03.2021 a 28.02.2022 | J10: Baixo Impacto | L10: • 08/11/2022 • Novo ■ Vorcon Auditoria & Consultoria
B11: V04 | C11: Conjunto de documentos anexados fora do mês correspondente no Balancete. | D11: Desorganização da documentação suporte dificultam a análise de todas as partes envolvidas. | E11: 418.07 | F11: A ausência de apresentação de forma tempestiva dos documentos financeiros poderá afetar diretamente o fluxo de caixa e o controle do financeiro do condomínio. | G11: Recomendamos que a prestação de contas seja realizada conforme o período correspondente as despesas. | H11: Operacional | I11: 6 - 01.1.6 - CRP - Voucher documental - 01.03.2021 a 28.02.2022 | J11: Baixo Impacto | L11: • 08/11/2022 • Novo ■ Vorcon Auditoria & Consultoria
B12: V05 | C12: Informações apresentado fora do mês correspondente na demonstração financeira. | D12: Verificamos que há desorganização das informações na demonstração financeira que dificultam na análise de todas as partes envolvidas. | E12: 418.07 | F12: A falta de apresentação de maneira tempestiva das informações financeiras poderá afetar diretamente o controle financeiro do condomínio e o entendimento dos Demonstrativos. | G12: Indicamos que as informações apresentadas nas Demonstrações Financeiras sejam realizadas conforme o período correspondente. | H12: Financeiro | I12: 6 - 01.1.6 - CRP - Voucher documental - 01.03.2021 a 28.02.2022 | J12: Baixo Impacto | L12: • 08/11/2022 • Novo ■ Vorcon Auditoria & Consultoria
B13: V06 | C13: Diferenças entre: Valor do comprovante de pagamento X Valor da documentação suporte. | D13: Identificamos que há diferença entre os valores apresentados não sendo justificados por parcelamentos ou multas. | E13: De - R$ 1.062,75 até R$ 3.750,00 | F13: Possíveis pagamentos realizados com valores incorretos podendo gerar prejuízos financeiros ao condomínio. | G13: Sugerimos que os pagamentos sejam realizados com os valores que constam no documento auxiliar. | H13: Financeiro | I13: 6 - 01.1.6 - CRP - Voucher documental - 01.03.2021 a 28.02.2022 | J13: Baixo Impacto | L13: • 08/11/2022 • Novo ■ Vorcon Auditoria & Consultoria
B14: V07 | C14: Pagamento realizado após data de vencimento com incidência de multa e juros. | D14: Verificamos que alguns pagamentos foram realizados após a data de vencimento acarretando em gastos adicionais. | E14: 10.37 | F14: Possibilidade do condomínio incorrer em gastos desnecessários | G14: Sugerimos que seja elaborado um controle de vencimento das despesas e que sejam efetuados os pagamentos até o vencimento. | H14: Financeiro | I14: 6 - 01.1.6 - CRP - Voucher documental - 01.03.2021 a 28.02.2022 | J14: Baixo Impacto | L14: • 08/11/2022 • Novo ■ Vorcon Auditoria & Consultoria
B15: V08 | C15: Pagamentos realizados antes da emissão da nota fiscal. | D15: Verificamos que ocorreram pagamentos onde a emissão da documentação fiscal é posterior a data em que a transação bancária foi realizada. | E15: 3563.16 | F15: O pagamento antes da emissão das notas fiscais traz uma vulnerabilidade a respeito do cumprimento das melhores práticas de gestão podendo gerar penalidades tributárias. | G15: Recomendamos que seja verificada a emissão da nota fiscal antes da realização do pagamento. | H15: Legal | I15: 6 - 01.1.6 - CRP - Voucher documental - 01.03.2021 a 28.02.2022 | J15: médio impacto | L15: • 08/11/2022 • Novo ■ Vorcon Auditoria & Consultoria
B16: V09 | C16: Emissão de nota de simples remessa após o pagamento do produto. | D16: Identificamos que foi emitida uma nota de simples remessa para produto pago através de outra nota fiscal | E16: 42.4 | F16: A emissão da nota fiscal de simples remessa após o pagamento do produto realizado através de outra nota poderá indicar falha operacional e causar prejuízos financeiros ao condomínio. | G16: Indicamos a Administração que promova melhoria dos controles internos visando mitigar falhas operacionais e possíveis prejuizos financeiros à entidade. | H16: Financeiro | I16: 6 - 01.1.6 - CRP - Voucher documental - 01.03.2021 a 28.02.2022 | J16: Baixo Impacto | L16: • 08/11/2022 • Novo ■ Vorcon Auditoria & Consultoria
B17: V10 | C17: Os balancetes sem aprovação dos conselheiros fiscais e do síndico no termo de aprovação. | D17: No período de 03/2021 a 02/2022 não constam as assinaturas do síndico e dos conselheiros fiscais para aprovação dos balancetes. Porém, conforme a Convenção do Subcondomínio Reserva das Plantas na cláusula 4.9.1 - f) "O Síndico de cada Subcondomínio tem as seguintes atribuições [...] rubrica[...] dos livros". Além disso, no item G-4.21-c) "Cada Conselho Fiscal [...] terá as seguintes atribuições: emitir parecer sobre as contas [...] do Síndico do Subcondomínio Residencial [...], conferindo-as, aprovando-as ou rejeitando-as". | E17: NA | F17: A falta das assinaturas dos conselheiros fiscais nos termos de aprovação dos balancetes indica que as contas do condomínio não foram submetidas ao exame, podendo acarretar a redução do nível de confiança dos demonstrativos e prejudicar a leitura dos usuários. | G17: Sugerimos que os conselheiros fiscais realizem o exame dos balancetes e caso ocorra a aprovação dos mesmos, confirmem com as suas assinaturas nos termos de aprovação. Mesmo com as demonstrações financeiras sendo auditadas mensalmente, é necessário a validação do conselho fiscal. | H17: Legal | I17: 9 - 01.1.9 - CRP - Resumo Convenção - 01.03.2021 a 28.02.2022 | J17: Alto Impacto | L17: • 08/11/2022 • Novo ■ Vorcon Auditoria & Consultoria
B18: V11 | C18: Falta de registro de Ata's em cartório | D18: Não identificamos o registro em cartório das Ata's: 16/12/2021, 09/09/2021, 14/10/2021, 27/01/2022, 03/02/2022. Conforme a Convenção do Subcondomínio Reserva das Plantas na cláusula 4.9.1 - f) "O Síndico de cada Subcondomínio tem as seguintes atribuições [...] Providenciar abertura, numeração, rubrica e encerramento dos livros, bem como o registro das atas em Cartório de Registro de Títulos e Documentos". | E18: NA | F18: Possível questionamento dos Condominos quanto a validação das Ata's por falta de registo no cartório. | G18: Sugerimos que haja registro das Ata's em cartório, conforme convenção. | H18: Legal | I18: 9 - 01.1.9 - CRP - Resumo Convenção - 01.03.2021 a 28.02.2022 | J18: médio impacto | L18: • 08/11/2022 • Novo ■ Vorcon Auditoria & Consultoria
B19: V12 | C19: Falta relatório de auditoria do período anterior. | D19: Conforme a Convenção do Subcondomínio Reserva das Plantas na cláusula 4.9.1 - h) "O Síndico de cada Subcondomínio tem as seguintes atribuições [...] Contratar, anualmente, empresa de auditoria para fiscalizar as contas do Subcondomínio." Dessa forma, não foi identificado o relatório da auditoria do período que antecedeu a auditoria atual (03/2021 a 02/2022). No entanto, analisamos conforme entendimento com o cliente que o condomínio realizou a auditoria em 2021 e não receberam o relatório. | E19: NA | F19: A ausência de contratação da auditoria e apresentação do relatório em relação ao período anterior, além de infringir a convenção condomonial, prejudica a transparência na prestação de contas podendo causar danos a situação financeira, econômica, legal e imagem da entidade. | G19: Recomendamos que a administração sempre realize auditorias preventivas. | H19: Estratégico | I19: 5 - 01.1.5 - CRP - Follow Up CCI - 01.03.2021 a 28.02.2022 | J19: Alto Impacto | L19: • 08/11/2022 • Novo ■ Vorcon Auditoria & Consultoria
B20: V13 | C20: Falta de Planejamento Orçamentário Anual | D20: Conforme a Convenção do Subcondomínio Reserva das Plantas na cláusula 4.36.1 "A assembleia geral ordinária do Condomínio realizar-se-á anualmente [...] outra assembleia geral ordinária do CONDOMÍNIO [Sic], sempre até o final do mês de novembro de cada ano e a ela competirá especificamente fixar o orçamento anual do CONDOMÍNIO para o exercicio social vindouro e a forma de cobrança das respectivas despesas." Dessa forma, não foi identificado o Planejamento Orçamentário para o ano de 2021. Além disso, identificamos nas Atas que o Sr. Marco Ribeiro, demonstrou as prinipais causas do aumento das despesas e informou que o condomíno está lidando com o mesmo planejamento orçamentário há 03 anos e que com a pandemia, todos os produtos e serviços tem sofrido aumentos fora do comum. | E20: NA | F20: A falta da elaboração do planejamento orçamentário poderá prejudicar o controle das contas condominiais e a prevenção dos gastos desnecerrários ou demasiados. | G20: Recomendamos que o o planejamento orçamentário ocorra dentro do período previsto em convenção. | H20: Estratégico | I20: 22 - 01.1.22 - CRP - Orçado X Realizado - 01.03.2021 a 28.02.2022 | J20: Alto Impacto | L20: • 08/11/2022 • Novo ■ Vorcon Auditoria & Consultoria
B21: V14 | C21: Sistema de medição da água realizado de forma não individualizada | D21: Segundo a ATA Reunião de Moradores do dia 09/09/2021 o "Sr. Roque Andrade entrou na tratativa da individualização da água e falou sobre os benefícios que isso traria por conta do consumo desigual entre as unidades [...]". Dessa forma, identificamos que o sistema de medição da água não é realizado de forma individualizada, infringindo assim, a cláusula 15.1 - e) da Convenção Condominial. | E21: NA | F21: A infração em relação a item previsto na Convenção Condominial pode gerar questionamentos, reclamações, impactos em relação a sustentabilidade e prejuizos de ordem legal para o condominio. | G21: Recomendamos que a administração analise a viabilidade da individualização de medição da água junto aos condominos e profissionais técnicos. Após isso, se for viável planeje a implementação e caso contrário, atualize a convenção para modificar a previsão desse item. | H21: Legal | I21: 9 - 01.1.9 - CRP - Resumo Convenção - 01.03.2021 a 28.02.2022 | J21: médio impacto | L21: • 08/11/2022 • Novo ■ Vorcon Auditoria & Consultoria
